File: data/XPS/l2800-5_all_syr11.vms
VAMAS Surface Chemical Analysis Standard Data Transfer Format 1988 May 4
Not Specified
Not Specified
Not Specified
Not Specified
13
Casa Info Follows CasaXPS Version 2.3.17PR1.1
3
Nb 3d
Nb 3d
O 1s
O 1s
Si 2p
Si 2p
Conversion string = d:\yugin\demchenko\casaxps\l2800-5\00m\si2p.dat
SourceAnalyserAngle: Not Specified
CasaRowLabel:nb3d.dat
CasaRowLabel:o1s.dat
CasaRowLabel:si2p.dat
NORM
REGULAR
3
1
Data Set
d
0
0
0
0
24
Nb3d
L2800-5
0
0
0
0
0
0
0
11
Casa Info Follows
1
Calib M = 202.574 A = 202.2 BE ADD
1
annot quant all v2315 InFWHM USE_TAG_LABEL Display 0.05 0.05 RGB(0,0,0) Font(14,18,0,0,Times New Roman)

1
CASA region (*Nb 3d*) (*U 2 Tougaard*) 1277.5303 1286.9584 8.21 2 0 0 589.18749 -650 0 0 (*Nb 3d*) 92.9064 0
2
CASA comp (*Nb 3d 5/2*) (*LA(1,3,5)*) Area 430.96026 0.001 10000000 -1 1 MFWHM 0.62570095 0.2 5 -1 1 Position 1284.3704 1269.974 1289.974 -1 1 RSF 8.21 MASS 92.9064 INDEX -1 (*Nb 3d*) CONST (**)
CASA comp (*Nb 3d3/2*) (*LA(1,3,5)*) Area 287.30828 0.001 10000000 0 0.66667 MFWHM 0.62570095 0.2 5 0 1 Position 1281.6504 0 0 0 -2.72 RSF 8.21 MASS 92.9064 INDEX -1 (*Nb 3d*) CONST (**)
XPS
0
Al
1486.6
1e+037
1e+037
1e+037
1e+037
1e+037
FAT
1e+037
1e+037
1e+037
1e+037
1e+037
1e+037
1e+037
1e+037
Nb3d

-1
Binding Energy
eV
217
-0.1
1
Counts
d
pulse counting
1
1
1e+037
1e+037
1e+037
1e+037
2
MFP Exponent
d
0
PROPAGATION_CONVERGED
d
1
201
0
1
954.127
902.411
882.455
920.96
927.32
869.468
889.991
937.585
860.78
956
934.943
914.693
869.864
912.567
978.749
919.721
910.767
934.409
953.244
910.992
917.532
960.681
914.545
865.563
817.603
905.181
909.563
921.753
970.731
926.527
934.332
882.593
860.495
948.036
908.847
856.316
866.351
917.055
885.987
936.309
941.573
920.172
912.528
826.832
920.616
889.536
884.125
915.299
875.368
876.784
883.335
887.045
946.027
918.536
885.901
936.909
886.139
863.455
871.528
815.384
873.112
912.92
892.888
951.144
927.756
872.761
975.252
933.832
934.244
929.224
856.229
866.665
886.373
888.587
909.127
853.821
914.036
908.521
927.113
905.793
877.397
935.157
882.195
917.928
852.109
929.78
865.701
907.949
922.465
851.333
917.397
865.515
820.423
892.447
965.136
896.068
900.325
926.54
945.005
922.585
930.465
834.135
923.524
949.708
958.031
973.365
945.333
896.568
986.803
1033.65
1007.01
1030.9
1044.18
1052.67
1023.14
1089.79
1135.07
1068.7
1069.05
1021.14
1041.82
950.292
941.171
936.776
1004.29
957.799
944.784
928.617
924.1
928.697
928.379
921.735
974.037
975.024
1005.75
1028.6
1013.83
1005.23
1026.23
1102.79
1133.93
1187.84
1185.86
1194.66
1242.21
1239.15
1172.27
1066.51
948.837
948.737
897.865
906.812
899.987
898.559
890.869
878.699
961.028
891.531
852.015
877.107
817.936
891.352
865.792
871.893
872.617
902.021
871.927
876.252
892.672
868.747
940.965
882.015
889.103
815.744
873.801
885.073
901.216
876.044
838.017
838.171
948.663
899.208
879.797
881.008
868.663
770.945
927.224
898.644
873.581
917.343
879.175
952.995
918.096
856.405
889.261
855.009
850.357
874.54
923.568
910.001
904.824
O1s
L2800-5
0
0
0
0
0
0
0
8
Casa Info Follows
1
Calib M = 202.574 A = 202.2 BE ADD
0
1
CASA region (*O 1s*) (*U 2 Tougaard*) 951.14407 957.23931 2.93 2 0 0 396.39491 -650 0 0 (*O 1s*) 15.9994 0
1
CASA comp (*O 1s *) (*GL(30)*) Area 10411.785 0.001 10000000 -1 1 MFWHM 1.524504 0.38 9.5 -1 1 Position 954.19791 945.974 961.974 -1 1 RSF 2.93 MASS 15.9994 INDEX -1 (*O 1s*) CONST (**)
XPS
0
Al
1486.6
1e+037
1e+037
1e+037
1e+037
1e+037
FAT
1e+037
1e+037
1e+037
1e+037
1e+037
1e+037
1e+037
1e+037
O1s

-1
Binding Energy
eV
541
-0.1
1
Counts
d
pulse counting
1
1
1e+037
1e+037
1e+037
1e+037
2
MFP Exponent
d
0
PROPAGATION_CONVERGED
d
1
161
0
1
2100.52
2064.74
2025.82
2007.84
2048.14
1973.08
1943.19
2045.36
2011
1971.12
1948.6
2046.6
1979.99
1982.13
2171.46
2080.08
2083.12
2046.26
2079.32
2005.96
2074.36
2006.9
2190.54
1930.06
2200.24
2030.14
2151.26
1977.65
2022.22
1959.13
2136.62
1943.65
2211.08
1951.95
2019.24
1821.3
2223.38
2007.08
1986.97
1933.12
2061.02
2021.98
2073.34
2130.66
2070.36
2065.06
1968.28
2046.5
2056.02
2000.82
1983.93
1982.01
2016.28
2052.18
1955.52
1934.91
2042.44
1976.53
2074.64
2128.32
2051.44
2027.76
2137.04
2149.1
2173.24
2299.18
2359.6
2503.68
2579.72
2817
3028.22
3488.34
3808.52
4316.66
4840.28
5445.22
6027.8
6564.04
6973.16
7478.78
7959.22
8173.12
8214.52
8223.3
8074.16
7725.42
7387.62
6751.84
6110.62
5627.22
4982.82
4639.36
3888.98
3687.68
3317.04
3165.34
2726.6
2631.06
2448.38
2361.58
2068.86
2255.96
2034.68
2096.84
2199.88
2156.8
2011.38
2065.88
1917.84
2021.58
1970.69
2034.9
1953.8
1975.08
1996.83
1890.67
2023.48
1916.07
1984.25
1857.27
1954.04
1900.76
2000.34
1967.03
1882.09
1879.57
1948.74
1888.1
1841.55
1979.32
1898.86
1958.32
1986.59
1947.92
1864.04
1808.26
2019.54
1869.86
1936.19
1944.93
1868.75
1913.27
2017.58
1955.85
1970.45
1997.46
1874.32
1870.3
1939.28
1969.03
1890.56
1853.16
1961.21
1904.19
1936.91
1918.15
1844.84
2003.14
1958.59
1972.84
1869.88
Si2p
L2800-5
0
0
0
0
0
0
0
11
Casa Info Follows
1
Calib M = 202.574 A = 202.2 BE ADD
0
1
CASA region (*Si 2p*) (*U 2 Tougaard*) 1380.5658 1389.1101 0.817 2 0 0 1993.5645 -650 0 0 (*Si 2p*) 28.0858 0
4
CASA comp (*Si 2p 3/2*) (*LA(1,1.5,250)*) Area 2928.1032 0.001 10000000 -1 1 MFWHM 0.7177845 0.24 6 -1 1 Position 1387.4327 1376.974 1392.974 -1 1 RSF 0.817 MASS 28.0858 INDEX -1 (*Si 2p*) CONST (**)
CASA comp (*Si 2p 1/2*) (*LA(1,1.5,250)*) Area 1464.0516 0.001 10000000 0 0.5 MFWHM 0.7177845 0.24 6 0 1 Position 1386.8027 0 0 0 -0.63 RSF 0.817 MASS 28.0858 INDEX -1 (*Si 2p*) CONST (**)
CASA comp (*Si 2p SiOx 1*) (*GL(30)*) Area 413.82459 0.001 10000000 -1 1 MFWHM 1.5603703 0.24 6 -1 1 Position 1384.6085 1376.974 1392.974 -1 1 RSF 0.817 MASS 28.0858 INDEX -1 (*Si 2p*) CONST (**)
CASA comp (*Si 2p SiOx 2*) (*GL(30)*) Area 1673.6335 0.001 10000000 -1 1 MFWHM 1.5603703 0.15253635 3.8134087 2 1 Position 1383.4803 1376.974 1392.974 -1 1 RSF 0.817 MASS 28.0858 INDEX -1 (*Si 2p*) CONST (**)
XPS
0
Al
1486.6
1e+037
1e+037
1e+037
1e+037
1e+037
FAT
1e+037
1e+037
1e+037
1e+037
1e+037
1e+037
1e+037
1e+037
Si2p

-1
Binding Energy
eV
110
-0.1
1
Counts
d
pulse counting
1
1
1e+037
1e+037
1e+037
1e+037
2
MFP Exponent
d
0
PROPAGATION_CONVERGED
d
1
161
0
1
363.472
429.674
426.162
419.702
392.278
412.096
439.802
412.014
401.716
463.216
369.018
354.29
386.306
393.526
387.452
350.454
371.904
417.964
354.6
393.14
346.42
375.798
355.928
370.492
423.468
364.284
394.42
383.486
360.23
351.846
349.782
372.276
352.046
334.424
357.286
367.974
348.14
359.806
348.252
351.574
340.16
344.586
373.872
361.816
346.006
366.06
437.776
344.664
383.872
387.968
397.102
513.318
529.65
572.832
626.282
669.678
704.33
846.178
842.216
874.088
1005.5
1183.1
1221.39
1246.75
1363.69
1400.66
1343.09
1388.04
1319.24
1255.72
1178.05
1141.64
979.534
1022.41
943.682
870.16
776.238
756.028
715.756
685.846
665.758
576.136
583.222
514.4
494.168
505.216
422.154
440.412
478.336
448.718
522.73
643.792
734.87
909.238
1182.57
1532.82
1848.99
2297.68
2537.92
2767.3
3083.28
3153.32
3427.56
3774.42
3756.5
3551.02
2998.88
2413.74
1851.32
1269.3
795.218
569.298
382.64
328.1
300.114
277.702
242.34
228.528
227.9
221.478
198.253
225.738
200.312
237.4
222.312
209.938
204.326
221.958
239.836
180.119
182.08
187.895
195.926
213.492
166.378
195.869
182.437
189.75
188.04
162.074
186.006
177.807
200.154
190.227
215.812
203.572
152.307
166.537
210.046
235.282
184.403
223.974
193.668
164.281
169.923
188.077
197.665
178.162
191.878
208.38
225.386
Nb3d
L2800-5
0
0
0
0
0
0
0
10
Casa Info Follows
1
Calib M = 202.574 A = 202.2 BE ADD
0
1
CASA region (*Nb 3d*) (*U 2 Tougaard*) 1277.5538 1287.6671 8.21 2 0 0 521.77964 -650 0 0 (*Nb 3d*) 92.9064 0
2
CASA comp (*Nb 3d 5/2*) (*LA(1,3,5)*) Area 476.26238 0.001 10000000 -1 1 MFWHM 0.54310435 0.2 5 -1 1 Position 1284.4147 1269.974 1289.974 -1 1 RSF 8.21 MASS 92.9064 INDEX -1 (*Nb 3d*) CONST (**)
CASA comp (*Nb 3d3/2*) (*LA(1,3,5)*) Area 317.50984 0.001 10000000 0 0.66667 MFWHM 0.54310435 0.2 5 0 1 Position 1281.6947 0 0 0 -2.72 RSF 8.21 MASS 92.9064 INDEX -1 (*Nb 3d*) CONST (**)
d:\yugin\demchenko\casaxps\l2800-5\01.vms
XPS
1
Al
1486.6
1e+037
1e+037
1e+037
1e+037
1e+037
FAT
1e+037
1e+037
1e+037
1e+037
1e+037
1e+037
1e+037
1e+037
Nb3d

-1
Binding Energy
eV
217
-0.1
1
Counts
d
pulse counting
1
1
1e+037
1e+037
1e+037
1e+037
2
MFP Exponent
d
0
PROPAGATION_CONVERGED
d
1
201
0
1
932.427
937.952
885.968
995.329
916.609
945.839
854.488
973.436
879.252
965.337
932.476
894.26
943.792
889.265
933.639
905.644
866.839
927.665
955.879
966.825
963.805
937.589
940.139
912.424
976.397
902.985
919.789
893.504
853.712
910.383
871.725
926.681
907.959
910.797
870.852
905.965
902.193
919.207
867.473
911.825
897.981
888.747
925.081
932.096
910.319
909.144
897.5
919.292
912.477
872.563
895.648
840.563
896.037
911.299
857.843
901.609
886.225
913.369
880.159
920.733
832.073
874.616
911.08
902.816
888.181
890.132
888.672
884.839
882.799
894.479
891.055
887.42
900.231
901.163
890.189
886.893
876.563
954.365
910.771
898.591
904.955
938.031
964.035
916
887.292
997.365
841.387
977.596
887.017
890.707
887.616
838.757
857.46
886.919
976.289
878.483
897.288
922.211
923.589
921.008
997.6
889.036
902.108
922.757
926.752
936.309
927.727
907.463
1043.04
973.699
1072.57
1020.09
1067.1
1089.62
1131.54
1072.37
1128.52
1178.99
1094.26
1100.61
967.072
1010.11
959.472
975.513
944.828
959.933
977.744
946.851
914.536
950.864
965.805
874.589
935.943
989.519
974.125
998.92
1057.98
1087.7
1096.81
1149.81
1136.27
1251.16
1210.76
1315.08
1364
1357.12
1287.29
1118.77
1095.83
978.635
885.341
950.649
866.855
874.951
860.676
943.924
874.125
902.299
918.832
869.896
899.725
879.811
897.24
857.449
918.999
933.273
943.512
891.979
960.185
911.623
900.248
885.328
927.181
851.557
904.557
915.204
847.757
940.645
909.517
888.969
842.487
827.328
872.145
877.847
979.393
891.269
840.947
916.644
857.909
903.729
946.095
890.796
896.871
853.924
940.769
863.04
942.315
895.528
935.668
881.145
864.391
O1s
L2800-5
0
0
0
0
0
0
0
9
Casa Info Follows
1
Calib M = 202.574 A = 202.2 BE ADD
0
1
CASA region (*O 1s*) (*U 2 Tougaard*) 949.91697 957.1349 2.93 2 0 0 2358.4569 -650 0 0 (*O 1s*) 15.9994 0
1
CASA comp (*O 1s *) (*GL(30)*) Area 7048.5962 0.001 10000000 -1 1 MFWHM 1.8698781 0.38 9.5 -1 1 Position 954.19766 945.974 961.974 -1 1 RSF 2.93 MASS 15.9994 INDEX -1 (*O 1s*) CONST (**)
d:\yugin\demchenko\casaxps\l2800-5\01.vms
XPS
1
Al
1486.6
1e+037
1e+037
1e+037
1e+037
1e+037
FAT
1e+037
1e+037
1e+037
1e+037
1e+037
1e+037
1e+037
1e+037
O1s

-1
Binding Energy
eV
541
-0.1
1
Counts
d
pulse counting
1
1
1e+037
1e+037
1e+037
1e+037
2
MFP Exponent
d
0
PROPAGATION_CONVERGED
d
1
161
0
1
2098
2128.26
2076.16
2154.78
2110.06
2042.56
2072.62
2179.54
2055.28
2001.34
2083.5
2066.54
2127.46
2165.34
2067.54
2076.36
2127.94
2067.42
2164.76
2064.78
2206.34
2076.3
2132.92
2183.24
1968.45
2019.72
2131.42
2032.12
2093.38
2027.88
2065.36
2117.88
2134.62
2099.56
2069.24
2220.74
2118.82
2147.84
2151.84
2153.46
2041.7
2172.66
2139.12
2085.94
2011.6
1934.3
2019.3
2109.24
2241.98
2151.4
2214.78
2149.64
2078.52
2159.14
2045.28
2143.02
2124.22
2017.66
2265.12
2225.42
2164.94
2241.88
2198.2
2234.1
2312.32
2320.92
2429.38
2547.66
2761.8
3016.52
3204.42
3273.22
3558.46
3699.68
4083.6
4273.24
4497.48
4812.36
5049.64
5100.94
5325.28
5334.94
5507.4
5386.46
5546.52
5108.46
4992.74
4910.78
4612.8
4179.9
4153.16
3983.08
3646.74
3415.02
3223.28
2973.46
2829.84
2559.92
2456.68
2353.46
2241.54
2263.48
2109.42
2043.52
2065.54
2036.66
2080.82
1975.65
2059.84
2069.08
1978.74
1946.85
1964.3
2064.86
1979.64
2023.44
2023.16
1929.58
1881.52
1882.66
2014.8
2025.82
1972.33
2056
1956.93
1991.79
2009.86
1941.12
1917.1
1919.15
1993.82
2045.02
1965.36
1897.29
2083.02
2077.06
1970.88
2030.82
2082.82
2006.64
2037.46
1992.14
2028.26
2001.04
2034.28
1945.23
2098.06
1923.69
2060.18
1853.06
2021.06
1974.46
1954.47
2005.5
1891.27
1951.41
2029.28
1962.16
1970.04
2007.48
2073.4
Si2p
L2800-5
0
0
0
0
0
0
0
13
Casa Info Follows
1
Calib M = 202.574 A = 202.2 BE ADD
0
1
CASA region (*Si 2p*) (*U 2 Tougaard*) 1380.4771 1389.0147 0.817 2 0 0 2430.2653 -650 0 0 (*Si 2p*) 28.0858 0
5
CASA comp (*Si 2p 3/2*) (*LA(1,1.5,250)*) Area 3056.5166 0.001 10000000 -1 1 MFWHM 0.75452565 0.24 6 -1 1 Position 1387.3358 1376.974 1392.974 -1 1 RSF 0.817 MASS 28.0858 INDEX -1 (*Si 2p*) CONST (**)
CASA comp (*Si 2p 1/2*) (*LA(1,1.5,250)*) Area 1528.2583 0.001 10000000 0 0.5 MFWHM 0.75452565 0.24 6 0 1 Position 1386.7058 0 0 0 -0.63 RSF 0.817 MASS 28.0858 INDEX -1 (*Si 2p*) CONST (**)
CASA comp (*Si 2p Si2O3*) (*GL(30)*) Area 680.20905 0.001 10000000 -1 1 MFWHM 1.8964566 0.24 6 3 1 Position 1384.8558 0 0 0 -2.48 RSF 0.817 MASS 28.0858 INDEX -1 (*Si 2p*) CONST (**)
CASA comp (*Si 2p SiO2*) (*GL(30)*) Area 1005.7441 0.001 10000000 -1 1 MFWHM 1.8964566 0.24 6 -1 1 Position 1383.4358 0 0 0 -3.9 RSF 0.817 MASS 28.0858 INDEX -1 (*Si 2p*) CONST (**)
CASA comp (*Si 2p Si2O*) (*GL(30)*) Area 706.56756 0.001 10000000 -1 1 MFWHM 1.4778316 0.24858463 6.2146156 -1 1 Position 1386.3858 0 0 0 -0.95 RSF 0.817 MASS 28.0858 INDEX -1 (*Si 2p*) CONST (**)
d:\yugin\demchenko\casaxps\l2800-5\01.vms
XPS
1
Al
1486.6
1e+037
1e+037
1e+037
1e+037
1e+037
FAT
1e+037
1e+037
1e+037
1e+037
1e+037
1e+037
1e+037
1e+037
Si2p

-1
Binding Energy
eV
110
-0.1
1
Counts
d
pulse counting
1
1
1e+037
1e+037
1e+037
1e+037
2
MFP Exponent
d
0
PROPAGATION_CONVERGED
d
1
161
0
1
456.176
490.44
503.574
519.946
489.98
465.822
474.448
435.356
466.67
533.116
432.586
458.27
468.054
477.644
509.946
456.188
482.434
541.032
458.656
503.494
399.072
488.88
436.39
450.02
497.526
458.602
499.46
390.572
441.918
442.008
467.124
418.98
429.948
417.89
485.992
491.474
430.262
400.508
480.986
357.224
493.15
446.636
418.018
471.65
398.606
447.58
448.182
497.196
448.926
504.958
438.682
534.468
550.904
624.528
581.034
646.384
669.346
716.796
767.304
836.424
804.42
900.326
856.406
800.392
952.25
937.64
955.91
941.782
892.508
920.58
964.81
943.174
886.032
954.816
842.69
845.428
907.778
844.63
853.782
790.514
843.776
780.512
829.392
811.972
828.296
858.492
940.222
987.344
963.998
1012.22
1221.21
1198.41
1524.87
1783.95
2222.86
2439.14
2837.98
3113.9
3359.78
3375.16
3555.88
3850.82
4003.76
4002.44
3634.54
3274.46
2649.94
2087.96
1436.66
989.636
658.006
489.392
334.724
312.596
281.668
234.602
276.04
291.614
251.9
234.154
246.02
222.392
267
224.488
232.144
228.02
211.56
208.568
238.23
221.622
213.768
212.46
228.124
217.606
227.89
220.144
184.483
233.318
194.332
196.111
207.9
192.233
209.744
190.128
219.704
182.23
243.62
188.724
245.91
263.522
188.29
181.761
213.716
184.426
217.958
207.674
212.11
212.35
215.71
203.824
182.355
Nb3d
L2800-5
0
0
0
0
0
0
0
12
Casa Info Follows
1
Calib M = 202.574 A = 202.2 BE ADD
0
1
CASA region (*Nb 3d*) (*U 2 Tougaard*) 1276.084 1286.919 8.21 2 0 0 2560.9916 -650 0 0 (*Nb 3d*) 92.9064 0
4
CASA comp (*Nb 3d5/2*) (*LA(1,3,5)*) Area 2684.8927 0.001 10000000 -1 1 MFWHM 0.51309659 0.2 5 -1 1 Position 1284.4382 1269.974 1289.974 -1 1 RSF 8.21 MASS 92.9064 INDEX -1 (*Nb 3d5/2*) CONST (**)
CASA comp (*Nb 3d3/2*) (*LA(1,3,5)*) Area 1798.8781 0.001 10000000 0 0.67 MFWHM 0.51309659 0.2 5 0 1 Position 1281.7182 0 0 0 -2.72 RSF 8.21 MASS 92.9064 INDEX -1 (*Nb 3d3/2*) CONST (**)
CASA comp (*Nb 3d5/2*) (*LA(1,3,5)*) Area 773.87052 0.001 10000000 -1 1 MFWHM 0.51309659 0.2 5 0 1 Position 1283.9131 1269.974 1289.974 -1 1 RSF 8.21 MASS 92.9064 INDEX -1 (*Nb 3d5/2*) CONST (**)
CASA comp (*Nb 3d3/2*) (*LA(1,3,5)*) Area 515.91368 0.001 10000000 2 0.66666667 MFWHM 0.51309659 0.14737469 3.6843673 0 1 Position 1281.1931 0 0 2 -2.72 RSF 8.21 MASS 92.9064 INDEX -1 (*Nb 3d3/2*) CONST (**)
d:\yugin\demchenko\casaxps\l2800-5\07.vms
XPS
7
Al
1486.6
1e+037
1e+037
1e+037
1e+037
1e+037
FAT
1e+037
1e+037
1e+037
1e+037
1e+037
1e+037
1e+037
1e+037
Nb3d

-1
Binding Energy
eV
217
-0.1
1
Counts
d
pulse counting
1
1
1e+037
1e+037
1e+037
1e+037
2
MFP Exponent
d
0
PROPAGATION_CONVERGED
d
1
201
0
1
1315.38
1229.57
1237.25
1177.43
1259.39
1309.01
1240.51
1215.32
1248.32
1194.91
1185.9
1176.34
1178.06
1190.2
1204.5
1245.43
1231.2
1168.61
1124.69
1260.7
1153.75
1162.55
1143.48
1125.66
1148.87
1109.11
1117.35
1050.44
1125.04
1116
1034.28
1120.6
1046.92
1049.84
1068.98
1069.8
1030.29
1040.83
1100.93
1137.53
1063.12
1020.58
1071.51
1007.02
1000.81
967.321
1061.69
1071.62
1005.69
1052.9
990.919
1036.71
1009.45
1004.24
969.248
960.153
1014.28
973.316
964.145
926.733
959.544
895.504
922.584
889.785
953.263
1008.81
961.221
924.175
948.375
870.521
960.072
969.064
917.1
947.481
915.036
898.495
897.679
980.996
857.549
887.832
870.864
852.172
905.292
838.253
991.24
937.485
923.945
932.871
915.297
930.032
889.081
1022.99
933.771
924.999
897.509
932.987
947.413
1011.45
991.451
1063.14
1004.47
1078.25
1068.95
1090.48
1141.53
1207.25
1228.26
1459.17
1585.39
1722.68
1837.12
1921.72
2053.36
2102.25
2340.64
2193.12
2327.4
2463.81
2252.36
2120.01
1694.87
1441.05
1238.09
1138.79
1083.17
1035.31
1048.84
1042.55
967.409
1018.28
1078.75
1144.48
1106.13
1280.63
1377.25
1621.87
1880.17
2041.04
2323.19
2568.81
2724.32
2878.44
3199.15
3339.76
3477.65
3348.32
2834.75
2090.29
1479.77
1162.4
973.735
890.288
794.496
789.031
712.907
732.739
753.415
705.131
708.321
700.404
761.143
769.028
739.504
703.609
659.635
735.195
639.136
771.548
710.799
726.224
662.964
708.952
714.923
768.585
706.949
687.58
675.113
718.217
740.779
783.608
702.855
702.76
711.135
724.26
746.001
721.099
672.24
724.053
724.216
765.807
683.375
722.573
726.835
725.319
761.92
690.74
667.1
715.856
694.747
756.104
726.695
O1s
L2800-5
0
0
0
0
0
0
0
9
Casa Info Follows
1
Calib M = 202.574 A = 202.2 BE ADD
0
1
CASA region (*O 1s*) (*U 2 Tougaard*) 951.97194 957.32724 2.93 2 0 0 0 -650 0 0 (*O 1s*) 15.9994 0
1
CASA comp (*O 1s*) (*GL(30)*) Area 597.4162 0.001 10000000 -1 1 MFWHM 1.707125 0.19875776 4.9689441 -1 1 Position 955.0696 945.974 961.974 -1 1 RSF 2.93 MASS 15.9994 INDEX -1 (*O 1s*) CONST (**)
d:\yugin\demchenko\casaxps\l2800-5\07.vms
XPS
7
Al
1486.6
1e+037
1e+037
1e+037
1e+037
1e+037
FAT
1e+037
1e+037
1e+037
1e+037
1e+037
1e+037
1e+037
1e+037
O1s

-1
Binding Energy
eV
541
-0.1
1
Counts
d
pulse counting
1
1
1e+037
1e+037
1e+037
1e+037
2
MFP Exponent
d
0
PROPAGATION_CONVERGED
d
1
161
0
1
2551.86
2478.56
2595.24
2332.74
2541.6
2450.94
2352.54
2424.16
2610.14
2602.14
2654.34
2553.24
2567.64
2421.34
2583.12
2429.64
2680.06
2556.1
2616.94
2550.64
2516.82
2535.52
2449.16
2540.02
2537.74
2510.5
2563.1
2435.32
2629.2
2602.12
2558.98
2476.06
2437.82
2466.24
2417.42
2578.28
2552.58
2649.16
2600.14
2548.24
2500.78
2539.48
2506.86
2538.84
2565.06
2633
2428.2
2553.34
2617.04
2511.3
2574.48
2571.86
2542.82
2548.88
2520.5
2531.56
2506.52
2518.26
2556.3
2532.16
2507.84
2535.32
2400.48
2455.78
2526.2
2520.72
2474.94
2559.54
2542.24
2573.52
2490.44
2645
2550.08
2498.5
2562.02
2612.04
2423.42
2744.6
2641
2739.5
2773
2639.52
2738.02
2671.26
2766.78
2702.52
2753.24
2729.88
2856.28
2787.68
2777.26
2765.14
2932.26
3012.22
2785.64
2925.48
2914.84
2833.9
2710.38
2710.5
2678.92
2695.26
2544.24
2506.46
2577.26
2528.3
2556.64
2588.44
2625.84
2557.06
2538.44
2577.96
2563.26
2530.88
2568.78
2508.76
2461.02
2439.38
2523.42
2599.02
2440.06
2679.04
2657.56
2656.06
2517.5
2545.7
2560.06
2697.18
2671.76
2600.7
2520.08
2505.54
2610.82
2542.16
2528.04
2458.68
2495.14
2463.48
2521.1
2659.08
2631.2
2528.68
2517.38
2602.82
2550.82
2500.98
2531.38
2555.84
2503.72
2570.88
2519.66
2520.88
2734.76
2598.54
2552.52
2601.72
2725.92
2498.46
2513.08
2522.38
2550.9
Si2p
L2800-5
0
0
0
0
0
0
0
13
Casa Info Follows
1
Calib M = 202.574 A = 202.2 BE ADD
0
1
CASA region (*Si 2p*) (*U 2 Tougaard*) 1382.3834 1388.9007 0.817 2 0 0 1602.5096 -650 0 0 (*Si 2p*) 28.0858 0
5
CASA comp (*Si 2p 3/2*) (*LA(1,1.5,250)*) Area 2719.4914 0.001 10000000 -1 1 MFWHM 0.67897466 0.24 6 -1 1 Position 1387.4755 1376.974 1392.974 -1 1 RSF 0.817 MASS 28.0858 INDEX -1 (*Si 2p*) CONST (**)
CASA comp (*Si 2p 1/2*) (*LA(1,1.5,250)*) Area 1359.7457 0.001 10000000 0 0.5 MFWHM 0.67897466 0.24 6 0 1 Position 1386.8455 0 0 0 -0.63 RSF 0.817 MASS 28.0858 INDEX -1 (*Si 2p*) CONST (**)
CASA comp (*Si 2p 3/2 Si-Nb*) (*LA(1,1.5,250)*) Area 1562.6519 0.001 10000000 -1 1 MFWHM 0.69405735 0.24 6 -1 1 Position 1387.2135 1376.974 1392.974 -1 1 RSF 0.817 MASS 28.0858 INDEX -1 (*Si 2p*) CONST (**)
CASA comp (*Si 2p 1/2 Si-Nb*) (*LA(1,1.5,250)*) Area 781.32597 0.001 10000000 2 0.5 MFWHM 0.69405735 0.16547927 4.1369818 2 1 Position 1386.5835 0 0 2 -0.63 RSF 0.817 MASS 28.0858 INDEX -1 (*Si 2p*) CONST (**)
CASA comp (*Si 2p SiOx*) (*GL(30)*) Area 138.07571 138.07571 138.09571 -1 1 MFWHM 1.46 1.46 1.48 -1 1 Position 1386.35 1386.33 1386.35 -1 -0.95 RSF 0.817 MASS 28.0858 INDEX -1 (*Si 2p*) CONST (**)
d:\yugin\demchenko\casaxps\l2800-5\07.vms
XPS
7
Al
1486.6
1e+037
1e+037
1e+037
1e+037
1e+037
FAT
1e+037
1e+037
1e+037
1e+037
1e+037
1e+037
1e+037
1e+037
Si2p

-1
Binding Energy
eV
110
-0.1
1
Counts
d
pulse counting
1
1
1e+037
1e+037
1e+037
1e+037
2
MFP Exponent
d
0
PROPAGATION_CONVERGED
d
1
161
0
1
745.068
633.09
665.25
604.736
631.352
612.304
620.372
695.344
606.42
604.728
656.65
597.806
606.812
559.856
543.928
623.208
570.582
583.86
580.376
659.914
618.19
607.54
580.122
587.448
536.536
600.008
571.96
564.634
656.806
478.952
573.758
566.272
575.428
577.846
561.48
538.978
545.498
510.366
544.236
561.798
583.682
552.046
490.552
550.204
533.284
536.262
554.366
603.528
548.374
568.12
572.946
504.678
589.778
510.256
527.5
504.222
539.954
524.498
583.068
500.426
498.256
521.238
498.008
488.71
563.846
516.59
514.326
543.974
535.71
526.29
585.286
496.316
559.542
538.072
516.778
567.4
519.838
545.616
514.404
521.676
580.418
605.914
499.376
644.798
560.714
705.954
735.796
703.972
712.812
807.852
1040.05
1189.95
1464.01
1755.88
2246.6
2671.48
3241.54
3730.8
4136.52
4450.18
4684
4984.74
5364.06
5452.72
5299.84
4935.96
4269.4
3270.34
2379.26
1677.76
1195.01
923.424
637.92
536.696
500.202
515.654
414.304
413.752
398.802
455.238
402.096
397.748
358.776
403.448
376.29
372.324
347.406
324.356
366.214
387.508
381.982
343.846
345.716
298.324
326.662
359.964
379.61
348.168
366.012
381.622
376.1
378.384
382.114
375.58
375.648
348.522
335.94
334
344.182
340.232
361.792
377.282
354.39
367.806
324.164
388.444
391.526
355.894
348.014
329.79
358.386
Nb3d
L2800-5
0
0
0
0
0
0
0
12
Casa Info Follows
1
Calib M = 202.574 A = 202.2 BE ADD
0
1
CASA region (*Nb 3d*) (*U 2 Tougaard*) 1274.8416 1286.2062 8.21 2 0 0 2399.7391 -650 0 0 (*Nb 3d*) 92.9064 0
4
CASA comp (*Nb-Nb 3d5/2*) (*LA(1,3,5)*) Area 11794.363 0.001 10000000 -1 1 MFWHM 0.62557255 0.2 5 -1 1 Position 1284.3472 1269.974 1289.974 -1 1 RSF 8.21 MASS 92.9064 INDEX -1 (*Nb 3d5/2*) CONST (**)
CASA comp (*Nb-Nb 3d3/2*) (*LA(1,3,5)*) Area 7902.2235 0.001 10000000 0 0.67 MFWHM 0.62557255 0.2 5 0 1 Position 1281.6272 0 0 0 -2.72 RSF 8.21 MASS 92.9064 INDEX -1 (*Nb 3d3/2*) CONST (**)
CASA comp (*Nb-Si 3d5/2*) (*LA(1,3,5)*) Area 10522.792 0.001 10000000 -1 1 MFWHM 0.51199874 0.089704905 2.2426226 -1 1 Position 1283.773 1269.974 1289.974 -1 1 RSF 8.21 MASS 92.9064 INDEX -1 (*Nb 3d5/2*) CONST (**)
CASA comp (*Nb-Si 3d3/2*) (*LA(1,3,5)*) Area 7050.2703 0.001 10000000 2 0.67 MFWHM 0.51199874 0.089704905 2.2426226 2 1 Position 1281.053 0 0 2 -2.72 RSF 8.21 MASS 92.9064 INDEX -1 (*Nb 3d3/2*) CONST (**)
d:\yugin\demchenko\casaxps\l2800-5\12.vms
XPS
12
Al
1486.6
1e+037
1e+037
1e+037
1e+037
1e+037
FAT
1e+037
1e+037
1e+037
1e+037
1e+037
1e+037
1e+037
1e+037
Nb3d

-1
Binding Energy
eV
217
-0.1
1
Counts
d
pulse counting
1
1
1e+037
1e+037
1e+037
1e+037
2
MFP Exponent
d
0
PROPAGATION_CONVERGED
d
1
201
0
1
2406.87
2300.69
2392.55
2241.88
2342.69
2452.69
2323.73
2404.08
2352.79
2255.11
2314
2283.43
2253.45
2302.57
2218.24
2319.81
2212.23
2184.63
2234.05
2141.49
2163.67
2174.52
2135.69
2238.63
2186.01
2065.11
2330.49
2140.04
2116.64
2112.71
2121.12
2081.15
2086.89
2024.87
1988.52
2104.51
1963.87
2010.96
2024.48
1960.81
1981.05
2049.88
1972.48
2093.88
2057.95
1934.59
1997.51
1883.03
1975.37
1924.15
1863.92
1899.87
1941.08
1902.65
1866.59
1871.69
1852.99
1933.92
1814.28
1888.89
1913.57
1804.81
1940.36
1875.67
1876.41
1845.32
1845.23
1859.67
1820.81
1779.12
1826.04
1864.44
1873.03
1855.99
1734.12
1908.84
1881.41
1858.55
1967.33
1888.17
1950.21
1931.25
1917.95
1963.65
2051.64
1965.33
2138.61
2120.03
2165.43
2269.55
2162.53
2290.49
2387.24
2382.45
2491.05
2572.6
2602.2
2726.25
2824.59
3113.63
3280.61
3627.88
3848.04
4436.59
5068.97
5850.72
6786.75
8002.19
8729.83
9524.93
10306
10546.5
10072.2
9595.53
9279.29
8527.76
7983.23
7516.63
6712.65
5762.71
4760.36
3866.55
3408.64
3076.97
2960.97
2959.33
2915.81
3201.11
3350.09
3699.03
4156.17
4939.45
5977.23
7432.88
9104.04
11072.5
13228
14871.1
15225.2
15124.4
13958
12601.7
11563
10788.9
10142.4
9163.2
7236.01
5145.72
3287.08
1945.87
1461.21
1101.81
926.019
854.937
737.271
685.927
655.799
615.773
592.631
607.789
578.64
599.833
575.956
528.427
513.365
535.731
506.731
488.427
550.26
513.492
539.357
486.837
521.307
510.815
529.941
535.603
501.527
486.625
490.603
479.805
525.477
518.343
484.273
533.513
524.129
489.812
519.103
504.207
498.211
488.131
509.832
490.807
535.139
488.099
464.024
460.433
498.596
465.932
507.527
479.072
492.785
O1s
L2800-5
0
0
0
0
0
0
0
9
Casa Info Follows
1
Calib M = 202.574 A = 202.2 BE ADD
0
1
CASA region (*O 1s*) (*U 2 Tougaard*) 951.77421 957.31077 2.93 2 0 0 11194.991 -650 0 0 (*O 1s*) 15.9994 0
1
CASA comp (*O 1s*) (*GL(30)*) Area 131.83468 0.001 10000000 -1 1 MFWHM 1.5503652 0.19875776 4.9689441 -1 1 Position 954.82274 945.974 961.974 -1 1 RSF 2.93 MASS 15.9994 INDEX -1 (*O 1s*) CONST (**)
d:\yugin\demchenko\casaxps\l2800-5\12.vms
XPS
12
Al
1486.6
1e+037
1e+037
1e+037
1e+037
1e+037
FAT
1e+037
1e+037
1e+037
1e+037
1e+037
1e+037
1e+037
1e+037
O1s

-1
Binding Energy
eV
541
-0.1
1
Counts
d
pulse counting
1
1
1e+037
1e+037
1e+037
1e+037
2
MFP Exponent
d
0
PROPAGATION_CONVERGED
d
1
161
0
1
2769.64
2709.2
2674.84
2759.5
2835.54
2847.42
2816.58
2779.62
2715.66
2891.46
2876.64
2782.84
2721.08
2780.04
2789.46
2771.82
2832.98
2815.7
2821.12
2707.28
2702.24
2822.8
2741.22
2804.34
2804.76
2792.38
2762.96
2880.8
2779.1
2808.7
2772.26
2902.92
2770.32
2893.72
2795.94
2763.94
2853.72
2843.06
2737.86
2772.26
2863.38
2848.44
2727.44
2783.1
2813.26
2799.84
2800.1
2777.42
2742.46
2740.3
2701.48
2784.76
2734.42
2852.74
2819.72
2832.26
2902.32
2772.54
2828.86
2848.12
2809.12
2945.4
2833.18
2775.84
2787.76
2807.76
2870.02
2830.24
2811.2
2762.46
2815.3
2890.24
2777.18
2837.72
2898.64
2797.6
2752.04
2936.56
2793.12
2895.98
2839.26
2901.08
2882.56
2918.2
2870.9
2875.66
2950.44
2949
3050.56
2967.88
2827.7
2857.48
2866.06
2867.66
2823.38
2917.9
2970.24
2931
2834.96
2938.46
2773.7
2884.8
2946.46
2935.96
2894.56
2750.18
2894.88
2824.18
2914.04
2840.26
2838.04
2832.26
2830.04
2895.12
2837.74
2981.66
2910.22
2740.52
2863.16
2759.18
2828.96
2855.72
2846.86
2905.86
2903.2
2821.4
2965.54
2892.28
2817.82
2828.08
2819.84
2893.64
2831.66
2760.68
2990.16
2891.54
2840.64
2867.9
2873.9
2814.06
3050
2960.78
3034.42
2775.72
2948.74
2852.68
2833.6
2891.46
2815.26
2932.02
2850.88
2971.98
2794.1
2881.38
2872.8
2789.66
2866.7
2891.18
2950.32
2836.5
2901.5
Si2p
L2800-5
0
0
0
0
0
0
0
13
Casa Info Follows
1
Calib M = 202.574 A = 202.2 BE ADD
0
1
CASA region (*Si 2p*) (*U 2 Tougaard*) 1382.3834 1388.9007 0.817 2 0 0 2705.4621 -650 0 0 (*Si 2p*) 28.0858 0
5
CASA comp (*Si 2p 3/2*) (*LA(1,1.5,250)*) Area 1785.3102 0.001 10000000 -1 1 MFWHM 0.73261789 0.24 6 -1 1 Position 1387.5015 1376.974 1392.974 -1 1 RSF 0.817 MASS 28.0858 INDEX -1 (*Si 2p*) CONST (**)
CASA comp (*Si 2p 1/2*) (*LA(1,1.5,250)*) Area 892.65508 0.001 10000000 0 0.5 MFWHM 0.73261789 0.24 6 0 1 Position 1386.8715 0 0 0 -0.63 RSF 0.817 MASS 28.0858 INDEX -1 (*Si 2p*) CONST (**)
CASA comp (*Si 2p 3/2 Si-Nb*) (*LA(1,1.5,250)*) Area 369.39432 0.001 10000000 -1 1 MFWHM 0.70667928 0.24 6 -1 1 Position 1387.8492 1376.974 1392.974 -1 1 RSF 0.817 MASS 28.0858 INDEX -1 (*Si 2p*) CONST (**)
CASA comp (*Si 2p 1/2 Si-Nb*) (*LA(1,1.5,250)*) Area 184.69716 0.001 10000000 2 0.5 MFWHM 0.70667928 0.16547927 4.1369818 2 1 Position 1387.2192 0 0 2 -0.63 RSF 0.817 MASS 28.0858 INDEX -1 (*Si 2p*) CONST (**)
CASA comp (*Si 2p SiOx*) (*GL(30)*) Area 138.07571 138.07571 138.09571 -1 1 MFWHM 1.48 1.46 1.48 -1 1 Position 1386.33 1386.33 1386.35 -1 -0.95 RSF 0.817 MASS 28.0858 INDEX -1 (*Si 2p*) CONST (**)
d:\yugin\demchenko\casaxps\l2800-5\12.vms
XPS
12
Al
1486.6
1e+037
1e+037
1e+037
1e+037
1e+037
FAT
1e+037
1e+037
1e+037
1e+037
1e+037
1e+037
1e+037
1e+037
Si2p

-1
Binding Energy
eV
110
-0.1
1
Counts
d
pulse counting
1
1
1e+037
1e+037
1e+037
1e+037
2
MFP Exponent
d
0
PROPAGATION_CONVERGED
d
1
161
0
1
476.684
490.568
553.748
556.332
540.17
539.802
553.134
504.54
539.864
538.008
498.032
514.042
552.236
565.394
538.242
529.44
508.656
548.338
651.36
536.218
474.566
549.444
546.13
500.202
561.438
519.73
510.572
563.586
555.948
458.85
531.256
472.972
586.756
510.608
543.744
494.39
505.65
528.202
514.164
554.724
489.866
575.94
541.534
575.466
470.272
511.682
500.698
546.932
508.48
554.776
551.546
543.948
548.21
554.302
627.338
559.844
546.36
555.952
569.912
562.268
552.39
574.054
562.248
559.282
518.162
556.08
577.438
502.454
542.014
567.6
543.836
566.532
601.748
504.056
631.14
513.164
575.952
606.168
627.514
578.278
634.14
629.586
606.728
681.02
604.39
610.464
739.012
621.232
726.876
726.948
767.988
810.144
868.64
964.678
1047.2
1275.75
1431.76
1771.63
1935.28
2143.02
2413.84
2477.4
2723.78
2861.82
2997.12
2964.68
2812.16
2565.7
2181.52
1729.84
1470.44
1053.47
912.978
752.168
641.534
566.87
554.978
460.866
482.54
517.404
447.998
502.128
491.644
508.336
505.648
484.42
468.012
516.054
487.492
462.978
501.66
487.444
475.824
426.654
463.85
499.67
466.374
471.748
485.974
459.856
442.42
507.41
412.596
468.258
470.096
495.81
489.65
476.176
501.872
446.702
497.312
468.586
485.786
438.02
479.536
479.968
464.018
492.042
462.072
410.242
457.886
Nb3d
L2800-5
0
0
0
0
0
0
0
14
Casa Info Follows
1
Calib M = 202.574 A = 202.2 BE ADD
1
annot quant all v2315 InFWHM USE_TAG_LABEL Display 0.05 0.05 RGB(0,0,0) Font(14,18,0,0,Times New Roman)

1
CASA region (*Nb 3d*) (*U 2 Tougaard*) 1272.6624 1285.7988 8.21 2 0 0 2298.4798 -650 0 0 (*Nb 3d*) 92.9064 0
4
CASA comp (*Nb 3d5/2*) (*LA(1,3,5)*) Area 30531.771 0.001 10000000 -1 1 MFWHM 0.62313203 0.2 5 -1 1 Position 1284.3238 1269.974 1289.974 -1 1 RSF 8.21 MASS 92.9064 INDEX -1 (*Nb 3d5/2*) CONST (**)
CASA comp (*Nb 3d3/2*) (*LA(1,3,5)*) Area 20456.287 0.001 10000000 0 0.67 MFWHM 0.62313203 0.2 5 0 1 Position 1281.6038 0 0 0 -2.72 RSF 8.21 MASS 92.9064 INDEX -1 (*Nb 3d3/2*) CONST (**)
CASA comp (*Nb 3d5/2*) (*LA(1,3,5)*) Area 1603.1381 0.001 10000000 -1 1 MFWHM 0.62313203 0.089704905 2.2426226 0 1 Position 1283.6738 0 0 0 -0.65 RSF 8.21 MASS 92.9064 INDEX -1 (*Nb 3d5/2*) CONST (**)
CASA comp (*Nb 3d3/2*) (*LA(1,3,5)*) Area 1074.1025 0.001 10000000 2 0.67 MFWHM 0.62313203 0.089704905 2.2426226 0 1 Position 1280.9438 0 0 0 -3.38 RSF 8.21 MASS 92.9064 INDEX -1 (*Nb 3d3/2*) CONST (**)
d:\yugin\demchenko\casaxps\l2800-5\21.vms
XPS
21
Al
1486.6
1e+037
1e+037
1e+037
1e+037
1e+037
FAT
1e+037
1e+037
1e+037
1e+037
1e+037
1e+037
1e+037
1e+037
Nb3d

-1
Binding Energy
eV
217
-0.1
1
Counts
d
pulse counting
1
1
1e+037
1e+037
1e+037
1e+037
2
MFP Exponent
d
0
PROPAGATION_CONVERGED
d
1
201
0
1
2917.65
2904.81
2873.8
2914.76
2983.05
2930.08
3027.57
2943.01
2882.99
3071.05
2926.39
3026.07
3066.59
2983.31
2964.4
2921.12
2942.24
2797.07
2937.09
2903.13
2993
2912.19
2958.23
2911.31
2956.08
2915.93
2981.83
2967.68
2931.52
2996.28
2893.76
2927.35
2881.73
2955.47
2965.11
3021.55
2881.15
2908.43
2927.11
2920.63
2788.61
2872.89
2815
2896.47
2816.65
3008.75
2725.81
2789.25
2839.55
2682.05
2760.39
2735.52
2763.35
2774.09
2630.31
2629.35
2682.59
2539.53
2597.81
2507.55
2509.61
2485.87
2520.24
2455.92
2498.83
2473.12
2463.53
2489.47
2411.93
2496.56
2470.11
2507.76
2294.33
2416.15
2477.95
2455.31
2434.03
2469.41
2496.65
2531.76
2531.81
2584.16
2553.88
2548.87
2610.43
2650.13
2619.99
2682.75
2746.27
2736.25
2891.45
2919.68
3081.01
3106.55
3199.25
3188.72
3311.04
3654.52
3745.41
3972.53
4319.61
4538.88
4820.16
5377.81
5671.23
6485.37
7083.52
7619.24
8512.2
9434.39
10706
11847
13344.7
14132.9
15466.4
16396
16190.7
15299.7
13773.3
11182.7
8868.83
6951.11
5339.45
4715.19
4320.36
4116.55
4069.65
4186.73
4424.15
4532.95
5271.28
5651.68
6365.49
6985.25
8089.57
9185.43
10749.4
12518.9
14474.9
16648
19631.9
22032.9
24188.3
25531.7
25103.2
21594.9
16047.1
10566.2
6316.08
3583.35
2433.69
1732.15
1351.89
1119.75
956.072
858.815
797.793
742.553
668.153
606.869
632.012
625.488
576.06
550.337
528.383
573.116
545.212
543.956
530.325
517.405
501.463
470.881
467.113
497.963
450.864
493.707
478.812
466.515
463.64
446.833
438.919
464.113
456.216
431.119
508.028
466.972
467.004
482.404
479.623
476.132
460.123
474.639
435.267
454.824
501.437
387.776
450.652
480.6
422.923
450.481
438.563
O1s
L2800-5
0
0
0
0
0
0
0
9
Casa Info Follows
1
Calib M = 202.574 A = 202.2 BE ADD
0
1
CASA region (*O 1s*) (*U 2 Tougaard*) 953.54419 958.59098 2.93 2 0 0 27384.336 -650 0 0 (*O 1s*) 15.9994 0
1
CASA comp (*O 1s*) (*GL(30)*) Area 467.94649 0.001 10000000 -1 1 MFWHM 1.1769777 0.26 6.5 -1 1 Position 955.94244 945.974 961.974 -1 1 RSF 2.93 MASS 15.9994 INDEX -1 (*O 1s*) CONST (**)
d:\yugin\demchenko\casaxps\l2800-5\21.vms
XPS
21
Al
1486.6
1e+037
1e+037
1e+037
1e+037
1e+037
FAT
1e+037
1e+037
1e+037
1e+037
1e+037
1e+037
1e+037
1e+037
O1s

-1
Binding Energy
eV
541
-0.1
1
Counts
d
pulse counting
1
1
1e+037
1e+037
1e+037
1e+037
2
MFP Exponent
d
0
PROPAGATION_CONVERGED
d
1
161
0
1
2250.16
2286.18
2239.1
2191.08
2193.24
2126.84
2271.44
2195.9
2341.78
2287.16
2256.62
2233.12
2243.7
2199.72
2157.94
2269.06
2424
2385.02
2220.44
2254.3
2334.96
2257.8
2207.38
2352.34
2236.42
2292.76
2282.08
2228.28
2418.66
2254.06
2329.58
2385.44
2243.12
2373.9
2400.62
2376.94
2386.3
2300.16
2205.82
2389.02
2296.22
2371.4
2263.84
2194.92
2309.48
2264.4
2286.54
2339.04
2219.62
2236.5
2240.2
2245.42
2386.36
2416.72
2343.16
2235.68
2222.06
2243.94
2304.6
2328.08
2189.36
2418.66
2326.48
2352.84
2326.9
2245.48
2243.52
2310.14
2347.68
2254.84
2348.22
2351.8
2256.52
2302.62
2466.88
2396.64
2408.58
2441.32
2439.36
2356.9
2420.5
2380.52
2425.46
2510.5
2512.88
2508.98
2405.8
2424.48
2545.26
2586.88
2411.32
2411.5
2510.62
2449
2529.82
2575.38
2528.94
2750.2
2659.74
2672.3
2636.26
2743.2
2691.36
2666.36
2637.18
2647.74
2436.8
2475.82
2308.16
2415.44
2296.48
2227.1
2313.52
2397.12
2262.7
2286.02
2372.06
2314.32
2457.4
2339.14
2222.34
2325.18
2372.78
2280.96
2274.32
2303.46
2298.48
2391.98
2384.22
2277.06
2496.78
2439.16
2400.82
2454.06
2420.24
2358.74
2387.52
2347.78
2443.34
2386.1
2524.36
2509.68
2479.5
2432.9
2250.42
2488.34
2457.14
2317.42
2223.9
2329.74
2323.38
2294.34
2474.48
2352.5
2401.94
2404.06
2499.2
2388.24
2436.04
2331.22
2387.04
Si2p
L2800-5
0
0
0
0
0
0
0
15
Casa Info Follows
1
Calib M = 202.574 A = 202.2 BE ADD
1
annot comps v2315 USE_TAG_LABEL InAtomStDev Display 0.05 0.05 RGB(0,0,0) Font(14,18,0,0,Times New Roman)

1
CASA region (*Si 2p*) (*U 2 Tougaard*) 1380.7019 1388.9196 0.817 2 0 0 1471.6604 -650 0 0 (*Si 2p*) 28.0858 0
5
CASA comp (*Si 2p 3/2*) (*LA(1,1.5,250)*) Area 166.16705 0.001 10000000 -1 1 MFWHM 0.89171624 0.24 6 -1 1 Position 1387.86 1387.84 1387.86 -1 1 RSF 0.817 MASS 28.0858 INDEX -1 (*Si 2p*) CONST (**)
CASA comp (*Si 2p 1/2*) (*LA(1,1.5,250)*) Area 83.083527 0.001 10000000 0 0.5 MFWHM 0.89171624 0.24 6 0 1 Position 1387.23 0 0 0 -0.63 RSF 0.817 MASS 28.0858 INDEX -1 (*Si 2p*) CONST (**)
CASA comp (*Si 2p 3/2 Si-Nb*) (*LA(1,1.5,250)*) Area 160.89098 0.001 10000000 -1 1 MFWHM 0.89171624 0.24 6 0 1 Position 1387.51 1387.49 1387.51 -1 1 RSF 0.817 MASS 28.0858 INDEX -1 (*Si 2p*) CONST (**)
CASA comp (*Si 2p 1/2 Si-Nb*) (*LA(1,1.5,250)*) Area 80.445488 0.001 10000000 2 0.5 MFWHM 0.89171624 0.16547927 4.1369818 0 1 Position 1386.88 0 0 2 -0.63 RSF 0.817 MASS 28.0858 INDEX -1 (*Si 2p*) CONST (**)
CASA comp (*Si 2p SiOx*) (*GL(30)*) Area 38.689478 0 1000 -1 1 MFWHM 2.2115852 2.2115852 2.2315852 -1 1 Position 1384.5947 1381.6 1387.6 -1 -0.95 RSF 0.817 MASS 28.0858 INDEX -1 (*Si 2p*) CONST (**)
d:\yugin\demchenko\casaxps\l2800-5\21.vms
XPS
21
Al
1486.6
1e+037
1e+037
1e+037
1e+037
1e+037
FAT
1e+037
1e+037
1e+037
1e+037
1e+037
1e+037
1e+037
1e+037
Si2p

-1
Binding Energy
eV
110
-0.1
1
Counts
d
pulse counting
1
1
1e+037
1e+037
1e+037
1e+037
2
MFP Exponent
d
0
PROPAGATION_CONVERGED
d
1
161
0
1
419.548
414.48
402.242
418.018
413.602
423.872
413.764
386.344
435.764
398.312
429.992
427.654
434.764
485.088
412.576
417.858
414.14
424.176
395.392
350.972
423.236
427.736
426.514
426.16
424.12
405.412
394.096
442.154
406.026
413.468
368.662
370.312
459.616
459.718
406.156
431.716
422.248
392.38
447.608
429.428
376.65
400.444
445.61
433.59
394.536
373.934
427.562
449.992
416.398
479.762
434.438
429.624
491.768
416.1
458.356
441.722
431.906
443.818
380.664
396.178
437.434
386.208
434.04
463.616
430.332
437.826
423.952
403.98
366.568
451.572
439.668
438.214
449.89
465.702
402.786
447.614
434.378
425.702
454.214
440.142
439.356
450.568
474.256
476.136
451.256
408.1
446.708
447.816
434.018
433.346
422.218
441.982
433.498
436.756
469.792
471.91
536.364
545.656
550.836
587.98
691.052
657.128
713.438
720.068
728.164
793.21
759.98
725.594
620.952
639.352
587.352
643.086
512.412
523.094
490.744
519.088
476.238
434.338
437.864
387.948
411.924
390.316
439.782
410.668
433.614
487.86
441.764
434.336
437.852
430.128
487.728
405.832
394.16
424.028
443.568
397.174
465.532
425.512
434.182
418.654
451.238
360.556
436.048
447.424
374.884
422.724
394.128
427.886
400.574
422.35
435.92
441.596
398.744
427.736
437.52
410.036
404.622
465.04
422.306
429.582
454.11
Nb3d
L2800-5
0
0
0
0
0
0
0
12
Casa Info Follows
1
Calib M = 202.574 A = 202.2 BE ADD
0
1
CASA region (*Nb 3d*) (*U 2 Tougaard*) 1275.4842 1285.8243 8.21 2 0 0 2465.5355 -650 0 0 (*Nb 3d*) 92.9064 0
4
CASA comp (*Nb 3d5/2*) (*LA(1,3,5)*) Area 18480.782 0.001 10000000 -1 1 MFWHM 0.62492138 0.2 5 -1 1 Position 1283.7527 1269.974 1289.974 -1 1 RSF 8.21 MASS 92.9064 INDEX -1 (*Nb 3d5/2*) CONST (**)
CASA comp (*Nb 3d3/2*) (*LA(1,3,5)*) Area 12382.124 0.001 10000000 0 0.67 MFWHM 0.62492138 0.2 5 0 1 Position 1281.0327 0 0 0 -2.72 RSF 8.21 MASS 92.9064 INDEX -1 (*Nb 3d3/2*) CONST (**)
CASA comp (*Nb 3d5/2*) (*LA(1,3,5)*) Area 1028.9565 0.001 10000000 -1 1 MFWHM 0.62492138 0.089704905 2.2426226 0 1 Position 1284.33 1284.33 1284.35 -1 1 RSF 8.21 MASS 92.9064 INDEX -1 (*Nb 3d5/2*) CONST (**)
CASA comp (*Nb 3d3/2*) (*LA(1,3,5)*) Area 689.40088 0.001 10000000 2 0.67 MFWHM 0.62492138 0.089704905 2.2426226 0 1 Position 1281.61 0 0 2 -2.72 RSF 8.21 MASS 92.9064 INDEX -1 (*Nb 3d3/2*) CONST (**)
d:\yugin\demchenko\casaxps\l2800-5\33.vms
XPS
33
Al
1486.6
1e+037
1e+037
1e+037
1e+037
1e+037
FAT
1e+037
1e+037
1e+037
1e+037
1e+037
1e+037
1e+037
1e+037
Nb3d

-1
Binding Energy
eV
217
-0.1
1
Counts
d
pulse counting
1
1
1e+037
1e+037
1e+037
1e+037
2
MFP Exponent
d
0
PROPAGATION_CONVERGED
d
1
201
0
1
1976.41
1975.92
2004.13
1900.28
1944.16
1981.96
1984.59
1898.13
1978.57
1957.19
1779.53
1901.24
1906.12
1847.29
1855.37
1852.81
1930.29
1874.84
1857.39
1918.16
1941.64
1778.33
1783.89
1834.99
1804.69
1817.43
1839.32
1800.2
1818.75
1838.76
1786.19
1835.75
1837.99
1826.53
1796.37
1869.84
1713.31
1878.77
1893.23
1878.59
1815.27
1811.03
1791.08
1838.24
1775.77
1750
1673.56
1759.95
1735.04
1811.75
1729.12
1797.93
1784.32
1740.75
1667.16
1841.15
1764.41
1773.53
1827.45
1808.25
1839.72
1892.23
1856.72
1813.11
1835.04
1730.44
1849.75
1846.91
1831.16
1776.96
1760.09
1899.91
1835.05
1819.17
1948.32
1876.01
1947.64
1943.12
1983.19
2027.11
1935.17
1997.64
2123.57
2107.08
2118.24
2128.08
2194.29
2193.85
2184.12
2365.07
2347.47
2502.81
2507.36
2718.44
2759.49
2976.53
3036.01
3274.76
3392.4
3731.13
4036.37
4476.88
5031.68
5731.2
6341.33
7151.84
7963.24
9108.52
9942.31
10270.4
10443.2
9820.83
9090.75
7750.85
6445.2
5340.29
4297.43
3741.11
3235.8
2951.55
2904.32
2862.55
2750.45
2938.4
2972.4
3220.01
3576.65
3875.17
4288.89
4959.77
5667.21
6716.25
7890.19
9492.27
11473.6
13458.9
14952.5
15827.7
15763.7
14413.7
11602.7
8541.01
6105.88
4142.45
2762.27
1910.37
1517.84
1199.99
1029.01
966.585
890.712
777.701
795.936
777.125
743.459
781.123
730.013
737.361
696.9
725.907
684.293
[...]
673.911
632.165
654.492
650.479
667.195
652.068
592.381
635.009
587.155
627.449
595.175
662.391
594.031
684.216
598.251
625.571
O1s
L2800-5
0
0
0
0
0
0
0
9
Casa Info Follows
1
Calib M = 202.574 A = 202.2 BE ADD
0
1
CASA region (*O 1s*) (*U 2 Tougaard*) 951.08214 960.21087 2.93 2 0 0 5235.3537 -650 0 0 (*O 1s*) 15.9994 0
1
CASA comp (*O 1s*) (*GL(30)*) Area 407.32322 0.001 10000000 -1 1 MFWHM 2.4313624 0.26 6.5 -1 1 Position 955.88664 945.974 961.974 -1 1 RSF 2.93 MASS 15.9994 INDEX -1 (*O 1s*) CONST (**)
d:\yugin\demchenko\casaxps\l2800-5\33.vms
XPS
33
Al
1486.6
1e+037
1e+037
1e+037
1e+037
1e+037
FAT
1e+037
1e+037
1e+037
1e+037
1e+037
1e+037
1e+037
1e+037
O1s

-1
Binding Energy
eV
541
-0.1
1
Counts
d
pulse counting
1
1
1e+037
1e+037
1e+037
1e+037
2
MFP Exponent
d
0
PROPAGATION_CONVERGED
d
1
161
0
1
960.992
1043.28
998.542
1091.17
1010.74
1021.75
999.528
1017.82
997.776
979.718
1022.64
994.856
1051.36
1022.18
1088.03
996.236
995.67
1061.22
1006.06
992.85
1083.99
1050.67
966.542
926.322
908.972
1043.19
970.454
1059.44
1052.73
981.876
984.338
1053.26
1097.35
949.978
1039.22
1025.33
1016.46
1033.18
952.386
1009.82
998.096
974.1
994.272
1017.99
1008.83
1074.11
1031.24
1027.72
1080.28
1063.36
1061.04
1089.39
968.506
1060.43
1073.8
1074.99
979.514
1121.16
1056.05
1085.72
1115.87
1065.29
1001.15
1031.09
945.526
1091.31
1031.9
1075.63
1063.57
1116.07
1010.89
1083.02
1056.3
1051.96
1076.82
1083.24
1107.99
1130.49
1099.94
1127.91
1067.04
1127.29
1118.32
1109.46
1090.61
1125.68
1042.4
1053.03
1105.95
1148.16
1169.09
1067.55
1161.84
1110.51
1177.3
1159.61
1141.63
1294.11
1164.23
1176.62
1266.11
1301.87
1198.28
1227.47
1145.18
1240.31
1116.63
1154.68
1103.56
1211.53
1108.06
1113.44
1018.58
1113.96
1134.65
981.262
1146.31
997.758
1069.72
1065.04
1100.66
996.768
1106.36
1158.45
1096.23
1010.46
1036.38
1079.76
1131.35
1042.57
1061.3
1099.2
1054.68
1126.2
949.69
1057.51
1071.78
990.042
1099.66
1026.55
1054.64
1013.25
1062.36
1065.39
1037.84
1062.9
1047.1
1087.49
1026.68
1097.14
1019.22
1039.49
1047.83
1080.66
1066.05
1093.76
1096.09
1071.11
1035.29
1010.92
1012.65
Si2p
L2800-5
0
0
0
0
0
0
0
13
Casa Info Follows
1
Calib M = 202.574 A = 202.2 BE ADD
0
1
CASA region (*Si 2p*) (*U 2 Tougaard*) 1383.9672 1389.5182 0.817 2 0 0 2745.2683 -650 0 0 (*Si 2p*) 28.0858 0
5
CASA comp (*Si 2p 3/2*) (*LA(1,1.5,250)*) Area 745.66113 0.001 10000000 -1 1 MFWHM 0.6482923 0.24 6 -1 1 Position 1387.9517 1376.974 1392.974 -1 1 RSF 0.817 MASS 28.0858 INDEX -1 (*Si 2p*) CONST (**)
CASA comp (*Si 2p 1/2*) (*LA(1,1.5,250)*) Area 372.83056 0.001 10000000 0 0.5 MFWHM 0.6482923 0.24 6 0 1 Position 1387.3217 0 0 0 -0.63 RSF 0.817 MASS 28.0858 INDEX -1 (*Si 2p*) CONST (**)
CASA comp (*Si 2p 3/2*) (*LA(1,1.5,250)*) Area 1519.2054 0.001 10000000 -1 1 MFWHM 0.72677839 0.24 6 -1 1 Position 1387.4705 1376.974 1392.974 -1 1 RSF 0.817 MASS 28.0858 INDEX -1 (*Si 2p*) CONST (**)
CASA comp (*Si 2p 1/2*) (*LA(1,1.5,250)*) Area 759.6027 0.001 10000000 2 0.5 MFWHM 0.72677839 0.24 6 2 1 Position 1386.8405 0 0 2 -0.63 RSF 0.817 MASS 28.0858 INDEX -1 (*Si 2p*) CONST (**)
CASA comp (*Si 2p SiOx*) (*GL(30)*) Area 138.07571 138.07571 138.09571 -1 1 MFWHM 1.48 1.46 1.48 -1 1 Position 1386.35 1386.33 1386.35 -1 -0.95 RSF 0.817 MASS 28.0858 INDEX -1 (*Si 2p*) CONST (**)
d:\yugin\demchenko\casaxps\l2800-5\33.vms
XPS
33
Al
1486.6
1e+037
1e+037
1e+037
1e+037
1e+037
FAT
1e+037
1e+037
1e+037
1e+037
1e+037
1e+037
1e+037
1e+037
Si2p

-1
Binding Energy
eV
110
-0.1
1
Counts
d
pulse counting
1
1
1e+037
1e+037
1e+037
1e+037
2
MFP Exponent
d
0
PROPAGATION_CONVERGED
d
1
161
0
1
290.376
313.79
309.96
322
318.046
335.61
310.378
321.642
284.068
329.472
264.622
302.356
305.898
319.694
334.022
298.046
314.278
288.194
305.698
313.856
304.71
340.982
286.404
287.608
282.438
286.41
345.478
287.742
288.02
333.906
312.052
280.282
286.162
301.838
321.966
288.346
356.96
258.798
268.38
291.968
370.802
280.804
349.33
275.136
323.552
314.528
333.684
327.432
274.776
315.678
339.656
344.188
342.086
312.066
320.094
320.292
345.786
335.454
320.352
324.204
337.938
343.486
329.522
256.838
310.052
315.31
290.4
292.202
297.508
272.202
282.546
309.622
302.018
365.384
304.406
303.994
308.196
315.806
278.13
296.978
345.13
333.654
302.184
314.198
389.552
346.468
381.792
344.648
387.988
441.684
440.464
494.318
565.19
719.392
765.02
969.346
1153.43
1393.79
1653.22
1882
2008
2184.04
2365.06
2623.48
2797.98
2570.8
2535.9
2371.5
2072.22
1845.8
1541.76
1291.51
1009.89
687.594
476.406
457.034
320.114
294.12
262.56
239.744
220.336
251.532
255.702
202.474
219.844
208.144
219.864
200.352
241.258
174.807
221.588
219.818
192.139
179.92
253.786
170.693
211.548
178.205
192.347
209.938
203.71
198.267
207.92
211.552
196.313
229.588
219.704
166.756
222.218
225.736
222.106
204.178
221.336
202.62
200.208
217.768
208.06
211.822
209.94
200.236
194.02
Nb3d
L2800-5
0
0
0
0
0
0
0
12
Casa Info Follows
1
Calib M = 202.574 A = 202.2 BE ADD
0
1
CASA region (*Nb 3d*) (*U 2 Tougaard*) 1273.029 1288.2021 8.21 2 0 0 1882.1815 -650 0 0 (*Nb 3d*) 92.9064 0
4
CASA comp (*Nb 3d5/2*) (*GL(30)*) Area 595.72848 0.001 10000000 -1 1 MFWHM 0.54121896 0.2 5 -1 1 Position 1284.1283 1278.6 1284.6 -1 1 RSF 8.21 MASS 92.9064 INDEX -1 (*Nb 3d5/2*) CONST (**)
CASA comp (*Nb 3d3/2*) (*GL(30)*) Area 399.13808 0.001 10000000 0 0.67 MFWHM 0.54121896 0.2 5 0 1 Position 1281.4083 0 0 0 -2.72 RSF 8.21 MASS 92.9064 INDEX -1 (*Nb 3d3/2*) CONST (**)
CASA comp (*Nb 3d5/2*) (*LA(1,3,5)*) Area 10986.667 0.001 10000000 -1 1 MFWHM 0.58381581 0.089704905 2.2426226 -1 1 Position 1283.7121 1269.974 1289.974 -1 1 RSF 8.21 MASS 92.9064 INDEX -1 (*Nb 3d5/2*) CONST (**)
CASA comp (*Nb 3d3/2*) (*LA(1,3,5)*) Area 7361.0587 0.001 10000000 2 0.66999926 MFWHM 0.58381581 0.089704905 2.2426226 2 1 Position 1280.9921 0 0 2 -2.72 RSF 8.21 MASS 92.9064 INDEX -1 (*Nb 3d3/2*) CONST (**)
d:\yugin\demchenko\casaxps\l2800-5\40.vms
XPS
40
Al
1486.6
1e+037
1e+037
1e+037
1e+037
1e+037
FAT
1e+037
1e+037
1e+037
1e+037
1e+037
1e+037
1e+037
1e+037
Nb3d

-1
Binding Energy
eV
217
-0.1
1
Counts
d
pulse counting
1
1
1e+037
1e+037
1e+037
1e+037
2
MFP Exponent
d
0
PROPAGATION_CONVERGED
d
1
201
0
1
1312.43
1278.91
1343.33
1242.3
1294.69
1362.64
1312.22
1202.44
1282.6
1319.24
1251.2
1255.05
1245.59
1302.36
1223.39
1332.43
1264.9
1221.38
1298.9
1257.21
1286.33
1261.51
1298.58
1226.33
1319.12
1219.87
1172.01
1185.92
1184.53
1257.67
1202.5
1212.38
1212.43
1165.61
1227.92
1185.67
1169.62
1137.11
1185.15
1183.97
1149.69
1127.71
1165.51
1220.38
1219.03
1086.95
1216.79
1226.19
1201.42
1176.61
1252.59
1249.45
1161
1152.28
1094.17
1136.57
1162.89
1210.45
1224
1061.69
1190
1234.68
1129.93
1154.22
1175.66
1150.1
1278.27
1218.74
1198.87
1216.89
1195.18
1244.86
1241.12
1275.92
1170.19
1239.87
1263.06
1336.56
1268.35
1356.64
1318.52
1376.39
1296.02
1280.07
1332.51
1482.75
1400.6
1473.04
1518.61
1519.47
1596.92
1569.89
1604.47
1740.99
1777.84
1837.71
1977.13
2016.64
2169.01
2261.07
2491.12
2803.35
3249.51
3530.31
3820.33
4462.39
5200.85
5650.03
6250.05
6579.96
6641.61
6244.65
5440.51
4670.27
3661.41
2999.73
2532.53
2164.29
1965.27
1789.56
1720.16
1783.37
1773.25
1832.49
1898.01
2033.28
2277.87
2398.68
2719.16
2985.12
3460.12
4125.13
4888.97
6101.65
7558.51
8774.61
9675.19
10183.6
9894.24
8683.75
6684.37
4996.11
3408.6
2302.57
1664.25
1214.38
1013.84
878.985
819.824
695.293
684.103
653.513
663.776
628.163
593.108
593.857
606.407
569.564
631.86
626.057
522.635
627.044
568.332
599.449
584.593
594.499
582.648
582.456
557.328
580.244
590.739
549.4
595.536
557.496
583.084
597.468
575.881
590.407
582.441
554.048
577.024
556.909
561.891
606.473
592.048
569.248
549.665
546.377
531.636
532.201
543.821
547.969
589.773
605.996
539.451
598.013
527.321
511.113
596.947
614.693
592.987
O1s
L2800-5
0
0
0
0
0
0
0
10
Casa Info Follows
1
Calib M = 202.574 A = 202.2 BE ADD
0
1
CASA region (*O 1s*) (*U 2 Tougaard*) 949.2461 958.95147 2.93 2 0 0 6317.5178 -650 0 0 (*O 1s*) 15.9994 0
2
CASA comp (*O 1s*) (*GL(30)*) Area 472.55263 0.001 10000000 -1 1 MFWHM 1.5914457 0.38 9.5 -1 1 Position 953.17888 945.974 961.974 -1 1 RSF 2.93 MASS 15.9994 INDEX -1 (*O 1s*) CONST (**)
CASA comp (*O 1s*) (*GL(30)*) Area 315.233 0.001 10000000 -1 1 MFWHM 1.690798 0.64689644 16.172411 -1 1 Position 955.09147 945.974 961.974 -1 1 RSF 2.93 MASS 15.9994 INDEX -1 (*O 1s*) CONST (**)
d:\yugin\demchenko\casaxps\l2800-5\40.vms
XPS
40
Al
1486.6
1e+037
1e+037
1e+037
1e+037
1e+037
FAT
1e+037
1e+037
1e+037
1e+037
1e+037
1e+037
1e+037
1e+037
O1s

-1
Binding Energy
eV
541
-0.1
1
Counts
d
pulse counting
1
1
1e+037
1e+037
1e+037
1e+037
2
MFP Exponent
d
0
PROPAGATION_CONVERGED
d
1
161
0
1
804.79
783.542
760.008
764.27
813.892
750.252
759.69
772.072
819.534
787.94
718.142
777.866
817.264
830.87
784.142
776.298
807.818
752.61
853.412
789.046
837.972
775.844
837.874
790.344
785.732
847.6
803.818
796.39
787.488
756.52
857.324
842.236
816.218
834.394
835.552
866.026
877.798
815.994
801.454
747.786
828.938
797.066
832.998
767.792
837.528
797.25
877.932
835.39
742.048
821.866
842.214
829.856
845.366
764.376
782.386
829.332
751.694
892.63
828.06
852.21
915.344
840.298
884.864
897.65
888.332
923.232
956.778
1059.48
1048.01
1057.87
1046.17
1035.62
997.912
1085.62
1066.85
1092.35
1045.76
958.002
983.532
984.662
968.174
984.074
960.332
1008.51
906.258
862.742
943.716
954.488
1000.26
937.13
1017.21
930.826
951.534
874.782
952.748
890.722
910.164
921.952
871.982
869.85
876.506
921.284
845.866
792.322
813.374
771.036
781.642
780.094
731.982
769.716
744.35
740.106
764.156
759.856
812.386
837.536
799.878
741.874
714.87
816.5
708.11
694.81
775.642
720.444
769.438
756.5
780.276
821.252
752.27
792.222
769.688
750.286
726.202
757.168
742.5
755.548
770.894
825.744
798.296
755.914
769.054
765.322
799.026
743.124
799.238
761.664
760.372
781.63
804.38
813.752
885.662
845.728
741.994
718.122
736.31
777.62
723.034
783.932
769.954
813.742
795.162
Si2p
L2800-5
0
0
0
0
0
0
0
14
Casa Info Follows
1
Calib M = 202.574 A = 202.2 BE ADD
0
1
CASA region (*Si 2p*) (*U 2 Tougaard*) 1379.3528 1390.7418 0.817 2 0 0 1681.0138 -650 0 0 (*Si 2p*) 28.0858 0
6
CASA comp (*Si 2p 3/2*) (*LA(1,1.5,250)*) Area 1846.0987 0.001 10000000 -1 1 MFWHM 0.70896495 0.24 6 -1 1 Position 1387.4556 1386.6 1388.6 -1 1 RSF 0.817 MASS 28.0858 INDEX -1 (*Si 2p*) CONST (**)
CASA comp (*Si 2p 1/2*) (*LA(1,1.5,250)*) Area 923.04935 0.001 10000000 0 0.5 MFWHM 0.70896495 0.24 6 0 1 Position 1386.8256 0 0 0 -0.63 RSF 0.817 MASS 28.0858 INDEX -1 (*Si 2p*) CONST (**)
CASA comp (*Si 2p Si2O3?*) (*GL(30)*) Area 183.23563 0.001 10000000 -1 1 MFWHM 1.9686631 0.1 3 3 1 Position 1384.63 1384.61 1384.63 -1 -2.0274047 RSF 0.817 MASS 28.0858 INDEX -1 (*Si 2p*) CONST (**)
CASA comp (*Si 2p SiOx*) (*GL(30)*) Area 377.24483 0.001 10000000 -1 1 MFWHM 1.9686631 0.1 6 -1 1 Position 1382.4761 1381.6 1383.6 -1 -5.1169184 RSF 0.817 MASS 28.0858 INDEX -1 (*Si 2p*) CONST (**)
CASA comp (*Si 2p 3/2 Si-Nb?*) (*LA(1,1.5,250)*) Area 1291.6098 0.001 10000000 -1 1 MFWHM 1.0821353 0.24 6 -1 1 Position 1387.3045 1376.974 1392.974 -1 1 RSF 0.817 MASS 28.0858 INDEX -1 (*Si 2p*) CONST (**)
CASA comp (*Si 2p 1/2 Si-Nb*) (*LA(1,1.5,250)*) Area 645.80488 0.001 10000000 4 0.5 MFWHM 1.0821353 0.16547927 4.1369818 4 1 Position 1386.6745 0 0 4 -0.63 RSF 0.817 MASS 28.0858 INDEX -1 (*Si 2p*) CONST (**)
d:\yugin\demchenko\casaxps\l2800-5\40.vms
XPS
40
Al
1486.6
1e+037
1e+037
1e+037
1e+037
1e+037
FAT
1e+037
1e+037
1e+037
1e+037
1e+037
1e+037
1e+037
1e+037
Si2p

-1
Binding Energy
eV
110
-0.1
1
Counts
d
pulse counting
1
1
1e+037
1e+037
1e+037
1e+037
2
MFP Exponent
d
0
PROPAGATION_CONVERGED
d
1
161
0
1
324.824
331.738
353.366
330.41
286.178
315.776
300.242
327.92
309.654
347.838
278.636
315.614
266.216
252.188
305.682
288.15
273.912
284.338
329.736
296.44
347.204
284.602
301.654
293.948
299.696
278.17
305.718
316.582
337.972
341.938
315.904
288.532
331.702
331.92
311.694
256.48
329.588
294.066
289.988
290.63
319.498
260.184
313.742
328.154
300.444
365.426
344.012
374.002
405.934
402.852
453.84
451.054
408.678
463.48
445.4
424.742
434.182
396.298
467.568
404.326
409.574
388.702
475.144
318.708
383.678
349.958
338.65
397.536
383.91
366.272
369.352
354.208
326.096
357.84
326.128
341.772
324.426
312.326
389.534
340.62
360.216
371.764
405.546
414.048
411.852
396.884
459.094
502.216
584.732
658.068
740.184
747.9
996.622
1133.58
1387.16
1678.76
2071.42
2343.4
2528.32
2883.16
3062.82
3243.82
3334.32
3548.44
3495.16
3291.68
2910.34
2292.68
1838.3
1291.93
855.492
606.75
422.248
322.198
273.776
223.91
180.196
192.097
213.768
168.293
181.531
166.372
183.648
170.193
185.943
172.315
169.841
154.247
163.716
164.236
165.653
154.031
157.912
162.239
139.952
152.202
149.767
156.29
171.824
156.003
175.997
151.983
168.273
181.918
193.372
162.321
172.097
154.006
183.821
162.187
150.068
199.972
199.739
154.119
140.293
174.134
179.918
156.259
193.58
162.091
183.239
Nb3d
L2800-5
0
0
0
0
0
0
0
10
Casa Info Follows
1
Calib M = 202.574 A = 202.2 BE ADD
0
1
CASA region (*Nb 3d*) (*U 2 Tougaard*) 1273.9659 1286.1654 8.21 2 0 0 2045.1207 -650 0 0 (*Nb 3d*) 92.9064 0
2
CASA comp (*Nb 3d5/2*) (*LA(1,3,5)*) Area 9096.0486 0.001 10000000 -1 1 MFWHM 0.67550763 0.089704905 2.2426226 -1 1 Position 1283.6727 1269.974 1289.974 -1 1 RSF 8.21 MASS 92.9064 INDEX -1 (*Nb 3d5/2*) CONST (**)
CASA comp (*Nb 3d3/2*) (*LA(1,3,5)*) Area 6094.3526 0.001 10000000 0 0.67 MFWHM 0.67550763 0.089704905 2.2426226 0 1 Position 1280.9527 0 0 0 -2.72 RSF 8.21 MASS 92.9064 INDEX -1 (*Nb 3d3/2*) CONST (**)
d:\yugin\demchenko\casaxps\l2800-5\44.vms
XPS
44
Al
1486.6
1e+037
1e+037
1e+037
1e+037
1e+037
FAT
1e+037
1e+037
1e+037
1e+037
1e+037
1e+037
1e+037
1e+037
Nb3d

-1
Binding Energy
eV
217
-0.1
1
Counts
d
pulse counting
1
1
1e+037
1e+037
1e+037
1e+037
2
MFP Exponent
d
0
PROPAGATION_CONVERGED
d
1
201
0
1
1014.27
1007.44
1054.55
1008.94
1014.57
1048.79
967.473
988.983
1020.13
958.896
1061.79
991.009
1030.52
978.74
984.273
958.492
941.58
1010.6
957.46
1046.46
978.887
996.769
908.864
923.883
971.727
967.757
984.1
1019.59
953.548
957.432
917.676
920.221
954.356
967.459
942.031
929.181
945.396
950.089
947.155
903.987
962.92
1025.95
933.519
968.012
947.884
982.492
951.452
927.835
935.064
970.988
1013.48
962.671
898.595
995.055
889.483
989.555
924.189
909.78
951.716
905.355
954.799
979.881
963.86
988.58
955.068
993.919
1011.12
937.473
937.969
974.127
986.468
976.221
1002.65
968.231
984.447
1053.68
1000.21
1125.12
1037.54
1022.52
1189.99
1132.37
1049.55
1124.03
1142.7
1192.29
1249.29
1252.05
1348.19
1285.27
1346.64
1394.2
1394.93
1484.41
1557.45
1617.07
1651.77
1806.23
1915.53
2136.13
2207.33
2334
2689.92
3014.75
3428.76
3786.92
4220.61
4669.41
4803.04
4965.88
4813.91
4329.27
3851.96
3219.44
2564.6
2171.71
1828.91
1743.28
1569.6
1545.31
1491.12
1531.53
1562.8
1597.6
1663.75
1872.99
2014.45
2124.64
2451.59
2684.77
3100.75
3739.88
4580.72
5310.09
6186.41
6732.88
7198.61
7201.76
6670.84
5434.31
4256.59
2991.13
2225.27
1524.15
1098.34
879.032
757.095
677.572
586.652
591.576
497.928
501.44
530.312
486.631
472.387
491.773
498.671
503.991
469.469
472.384
516.256
466.017
446.212
462.887
440.131
433.684
482.307
495.733
440.832
499.396
493.175
465.655
436.089
434.576
473.017
432.452
470.693
443.017
526.78
463.116
449.571
447.095
478.204
473.14
476.644
479.735
451.289
428.893
486.309
413.557
447.911
426.447
453.591
445.424
473.472
489.225
449.676
514.089
461.375
455.06
445.18
O1s
L2800-5
0
0
0
0
0
0
0
10
Casa Info Follows
1
Calib M = 202.574 A = 202.2 BE ADD
0
1
CASA region (*O 1s*) (*U 2 Tougaard*) 949.41188 958.32431 2.93 2 0 0 2596.4732 -650 0 0 (*O 1s*) 15.9994 0
2
CASA comp (*O 1s*) (*GL(30)*) Area 987.16849 0.001 10000000 -1 1 MFWHM 1.4409921 0.46 11.5 -1 1 Position 955 955 955.2 -1 1 RSF 2.93 MASS 15.9994 INDEX -1 (*O 1s*) CONST (**)
CASA comp (*O 1s*) (*GL(30)*) Area 3544.6196 0.001 10000000 -1 1 MFWHM 1.6849208 0.4381555 10.953887 -1 1 Position 953.48447 945.974 961.974 -1 1 RSF 2.93 MASS 15.9994 INDEX -1 (*O 1s*) CONST (**)
d:\yugin\demchenko\casaxps\l2800-5\44.vms
XPS
44
Al
1486.6
1e+037
1e+037
1e+037
1e+037
1e+037
FAT
1e+037
1e+037
1e+037
1e+037
1e+037
1e+037
1e+037
1e+037
O1s

-1
Binding Energy
eV
541
-0.1
1
Counts
d
pulse counting
1
1
1e+037
1e+037
1e+037
1e+037
2
MFP Exponent
d
0
PROPAGATION_CONVERGED
d
1
161
0
1
953.42
1024.97
939.09
945.39
909.054
936.536
924.028
934.37
920.082
964.832
1059.45
1031.87
957.454
976.082
924.162
868.662
911.84
930.37
915.178
964.072
939.518
946.358
949.184
1030.41
954.502
1015.77
952.918
1064.86
975.832
962.778
994.248
989.952
985.764
1098.45
905.514
1043.26
928.904
987.04
928.232
958.386
1049.94
976.418
963.634
906.466
953.256
936.198
985.304
896.526
933.502
886.15
924.502
916.39
997.678
875.786
888.124
1015.95
1013.9
1014.67
1070.04
1051.93
1084.62
1198.3
1299.08
1478.91
1444.93
1707.12
1835.32
2049.7
2192.84
2310.82
2458.48
2658.34
2725.52
2749.56
2767.46
2935.84
2860.38
2760.02
2770.94
2646.28
2583.42
2393.22
2303.74
2218.58
2318.08
2060.36
2104.76
2012.32
1917.96
1754.62
1624.09
1669.72
1598.25
1547.49
1392.78
1325.21
1216.63
1180.29
1279.18
1123.05
969.894
1017.01
922.642
937.372
894.182
873.994
830.81
927.392
924.15
874.066
821.906
851.426
830.54
842.762
904.812
804.986
849.38
844.454
796.1
831.392
860.012
943.268
810.182
834.232
871.718
818.318
772.346
841.926
885.074
826.786
823.724
839.454
774.262
731.964
901.886
792.86
832.1
794.256
772.688
809.574
827.312
803.954
850.178
809.784
805.398
781.488
835.572
896.634
759.824
873.022
744.062
818.066
809.534
824.324
824.44
911.864
847.19
813.664
741.434
849.458
794.514
Si2p
L2800-5
0
0
0
0
0
0
0
12
Casa Info Follows
1
Calib M = 202.574 A = 202.2 BE ADD
0
1
CASA region (*Si 2p*) (*U 2 Tougaard*) 1379.5809 1389.2917 0.817 2 0 0 1602.6263 -650 0 0 (*Si 2p*) 28.0858 0
4
CASA comp (*Si 2p 3/2*) (*LA(1,1.5,250)*) Area 1512.2358 0.001 10000000 -1 1 MFWHM 0.85119002 0.24 6 -1 1 Position 1387.4236 1376.974 1392.974 -1 1 RSF 0.817 MASS 28.0858 INDEX -1 (*Si 2p*) CONST (**)
CASA comp (*Si 2p 1/2*) (*LA(1,1.5,250)*) Area 756.11791 0.001 10000000 0 0.5 MFWHM 0.85119002 0.24 6 0 1 Position 1386.7936 0 0 0 -0.63 RSF 0.817 MASS 28.0858 INDEX -1 (*Si 2p*) CONST (**)
CASA comp (*Si 2p Si2O?*) (*GL(30)*) Area 791.81332 0.001 10000000 -1 1 MFWHM 2.066822 0.13921092 3.480273 3 1 Position 1385.7945 1384.6 1386.6 -1 -2.48 RSF 0.817 MASS 28.0858 INDEX -1 (*Si 2p*) CONST (**)
CASA comp (*Si 2p SiO2?*) (*GL(30)*) Area 1503.2791 0.001 10000000 -1 1 MFWHM 2.066822 0.1 6 -1 1 Position 1382.9226 1381.6 1383.6 -1 -3.9 RSF 0.817 MASS 28.0858 INDEX -1 (*Si 2p*) CONST (**)
d:\yugin\demchenko\casaxps\l2800-5\44.vms
XPS
44
Al
1486.6
1e+037
1e+037
1e+037
1e+037
1e+037
FAT
1e+037
1e+037
1e+037
1e+037
1e+037
1e+037
1e+037
1e+037
Si2p

-1
Binding Energy
eV
110
-0.1
1
Counts
d
pulse counting
1
1
1e+037
1e+037
1e+037
1e+037
2
MFP Exponent
d
0
PROPAGATION_CONVERGED
d
1
161
0
1
270.512
269.832
256.41
231.856
261.778
258.304
256.21
301.324
248.344
269.81
238.272
269.758
279.736
222.292
277.772
268.542
262.332
305.216
240.568
295.222
262.38
281.844
258.224
283.856
224.586
267.122
236.69
261.974
273.552
238.65
277.958
275.588
255.792
238.284
236.316
259.702
289.822
292.284
297.986
282.332
325.732
327.722
304.358
341.878
377.964
421.678
403.222
511.042
427.126
600.758
612.52
658.434
697.832
730.34
748.872
865.65
874.298
944.514
902.09
901.372
809.79
924.36
812.694
897.514
740.634
721.866
745.992
722.928
610.846
635.856
653.582
596.282
528.242
527.886
537.876
499.784
448.636
505.816
494.434
529.59
489.88
482.696
603.352
524.688
541.926
581.852
588.358
635.298
668.194
699.122
811.532
795.526
755.162
906.176
1083.45
1089.68
1288.76
1411.57
1535.3
1692.15
1746.28
1734.12
1869.58
1873.61
1841.37
1779.2
1477.56
1370.4
1008.57
779.602
631.688
406.914
351.58
278.028
210.13
223.716
196.341
164.131
153.483
168.273
191.787
160.074
162.077
156.437
185.557
178.193
184.017
164.148
181.943
196.099
181.92
175.872
195.705
172.011
167.943
138.361
151.702
150.256
165.83
144.403
179.889
195.77
179.784
114.455
167.526
150.483
183.716
173.67
138.568
163.849
170.128
157.832
158.213
182.281
183.844
183.494
158.304
160.068
157.972
175.523
154.406
end of experiment