File: data/XPS/L2822-6_all.vms
VAMAS Surface Chemical Analysis Standard Data Transfer Format 1988 May 4
Not Specified
Not Specified
Not Specified
Not Specified
17
Casa Info Follows CasaXPS Version 2.3.17PR1.1
5
Si 2p 1/2
Si 2p 1/2
Si 2p 3/2
Si 2p 3/2
Si 2p Si2O
Si 2p Si2O
Si 2p Si2O3
Si 2p Si2O3
Si 2p SiO2
Si 2p SiO2
Conversion string = d:\yugin\demchenko\casaxps\l2822-6\00m\si2p.dat
SourceAnalyserAngle: Not Specified
CasaRowLabel:nb3d.dat
CasaRowLabel:o1s.dat
CasaRowLabel:si2p.dat
NORM
REGULAR
3
1
Data Set
d
0
0
0
0
19
Nb3d
L2822-6
0
0
0
0
0
0
0
10
Casa Info Follows
0
0
1
CASA region (*Nb 3d*) (*U 2 Tougaard*) 1274.8416 1286.2062 8.21 2 0 0 2399.7391 -650 0 0 (*Nb 3d*) 92.9064 0
4
CASA comp (*Nb-Nb 3d5/2*) (*LA(1,3,5)*) Area 0.001 0.001 10000000 -1 1 MFWHM 0.2 0.2 5 -1 1 Position 1289.974 1269.974 1289.974 -1 1 RSF 8.21 MASS 92.9064 INDEX -1 (*Nb 3d5/2*) CONST (**)
CASA comp (*Nb-Nb 3d3/2*) (*LA(1,3,5)*) Area 0.00067 0.001 10000000 0 0.67 MFWHM 0.2 0.2 5 0 1 Position 1287.254 0 0 0 -2.72 RSF 8.21 MASS 92.9064 INDEX -1 (*Nb 3d3/2*) CONST (**)
CASA comp (*Nb-Si 3d5/2*) (*LA(1,3,5)*) Area 54.796767 0.001 10000000 -1 1 MFWHM 0.35167756 0.089704905 2.2426226 -1 1 Position 1283.5626 1269.974 1289.974 -1 1 RSF 8.21 MASS 92.9064 INDEX -1 (*Nb 3d5/2*) CONST (**)
CASA comp (*Nb-Si 3d3/2*) (*LA(1,3,5)*) Area 36.713834 0.001 10000000 2 0.67 MFWHM 0.35167756 0.089704905 2.2426226 2 1 Position 1280.8426 0 0 2 -2.72 RSF 8.21 MASS 92.9064 INDEX -1 (*Nb 3d3/2*) CONST (**)
XPS
0
Al
1486.6
1e+037
1e+037
1e+037
1e+037
1e+037
FAT
1e+037
1e+037
1e+037
1e+037
1e+037
1e+037
1e+037
1e+037
Nb3d

-1
Binding Energy
eV
217
-0.1
1
Counts
d
pulse counting
1
1
1e+037
1e+037
1e+037
1e+037
2
MFP Exponent
d
0
PROPAGATION_CONVERGED
d
1
201
0
1
722.963
727.848
771.521
756.923
753.244
686.269
683.811
743.748
697.456
729.104
697.812
727.693
718.981
740.796
708.792
774.127
691.048
709.257
730.392
720.915
790.099
743.591
726.743
702.852
729.224
746.293
703.432
759.717
639.809
748.845
748.189
709.397
682.964
703.783
741.757
694.252
810.629
736.1
697.599
714.44
743.064
744.613
798.712
733.581
746.361
680.381
674.776
687.996
724.381
759.369
755.203
768.996
741.103
738.951
706.797
714.801
702.856
790.081
741.14
751.752
713.829
781.855
826.031
720.733
750.071
693.904
687.036
756.847
779.919
712.024
719.568
689.441
718.303
703.035
755.315
690.289
710.424
762.509
748.087
758.335
726.599
759.037
750.607
717.271
725.617
739.668
766.589
743.207
725.117
713.839
763.407
722.063
792.955
765.603
747.679
724.012
755.869
773.004
788.855
760.545
732.856
644.649
788.113
752.081
780.464
729.321
727.021
736.476
787.733
740.805
794.549
787.973
771.981
794.341
751.915
745.239
784.153
774.501
733.055
806.983
745.432
712.244
754.335
745.072
759.769
711.432
782.688
775.737
780.977
706.936
757.263
796.343
774.667
752.893
759.135
800.481
748.504
786.545
817.969
863.337
807.455
807.541
776.244
786.672
746.168
728.136
724.185
782.555
766.099
795.357
770.724
775.559
746.544
755.42
808.648
731.343
751.583
726.155
755.121
737.913
725.396
759.333
737.419
769.788
719.485
770.559
754.992
747.708
718.648
750.828
799.896
758.473
768.06
714.596
738.257
704.021
752.632
774.784
747.668
744.483
769.315
728.328
699.691
762.833
759.855
749.924
680.564
739.965
755.712
753.459
758.761
760.78
789.351
714.233
780.441
682.979
802.532
742.076
772.379
708.396
782.409
O1s
L2822-6
0
0
0
0
0
0
0
5
Casa Info Follows
0
0
0
0
XPS
0
Al
1486.6
1e+037
1e+037
1e+037
1e+037
1e+037
FAT
1e+037
1e+037
1e+037
1e+037
1e+037
1e+037
1e+037
1e+037
O1s

-1
Binding Energy
eV
541
-0.1
1
Counts
d
pulse counting
1
1
1e+037
1e+037
1e+037
1e+037
1
MFP Exponent
d
0
161
0
1
745.062
710.602
779.168
728.478
789.178
741.292
824.838
759.032
789.264
766.258
817.756
769.938
803.128
735.066
775.562
774.302
777.642
726
776.298
782.218
822.98
781
809.302
734.644
749.974
791.678
807.724
826.346
790.464
781.606
744.164
721.748
792.296
803.358
746.326
849.772
782.278
708.142
732.284
831.054
781.216
769.622
744.306
793.548
802.426
795.404
758.286
784.272
775.898
749.974
831.048
756.778
795.642
754.494
807.46
772.482
800.46
850.798
803.286
891.508
828.356
891.096
1024.22
1120
1202.53
1387.25
1484.77
1698.63
1987.83
2198.54
2577.66
2963.82
3468.76
3706.92
4461.6
4731.4
5057.26
5595
5721.4
5648.94
5782.36
5461.06
5332.02
4734.86
4436.2
4113.04
3869.76
3324.98
2898.96
2700.58
2246.48
2112.06
1883.03
1671.8
1415.18
1430.59
1215.16
1117.99
1041.55
941.582
934.356
935.302
886.404
784.156
820.232
857.508
821.66
710.934
787.526
742.244
730.164
761.838
760.148
746.054
720.634
769.426
698.678
763.384
719.872
685.87
712.046
718.216
743.548
706.012
701.698
702.606
693.54
706.92
713.606
763.508
676.602
737.316
688.872
749.366
722.022
647.278
742.892
759.982
650.818
682.968
716.52
669.894
677.806
688.196
722.944
703.08
772.208
790.756
657.11
724.952
676.012
668.326
694.23
711.87
755.394
649.018
685.884
723.83
713.1
670.482
656.134
Si2p
L2822-6
0
0
0
0
0
0
0
11
Casa Info Follows
0
0
1
CASA region (*Si 2p*) (*U 2 Tougaard*) 1380.4771 1389.0147 0.817 2 0 0 2172.8443 -650 0 0 (*Si 2p*) 28.0858 0
5
CASA comp (*Si 2p 3/2*) (*LA(1,1.5,250)*) Area 2352.121 0.001 10000000 -1 1 MFWHM 0.79516102 0.79170163 0.81170163 -1 1 Position 1386.9352 1386.9255 1386.9455 -1 1 RSF 0.817 MASS 28.0858 INDEX -1 (*Si 2p*) CONST (**)
CASA comp (*Si 2p 1/2*) (*LA(1,1.5,250)*) Area 1176.0605 0.001 10000000 0 0.5 MFWHM 0.79516102 0.24 6 0 1 Position 1386.3052 0 0 0 -0.63 RSF 0.817 MASS 28.0858 INDEX -1 (*Si 2p*) CONST (**)
CASA comp (*Si 2p Si2O3*) (*GL(30)*) Area 295.1548 0.001 10000000 -1 1 MFWHM 1.822599 0.24 6 3 1 Position 1384.4552 0 0 0 -2.48 RSF 0.817 MASS 28.0858 INDEX -1 (*Si 2p*) CONST (**)
CASA comp (*Si 2p SiO2*) (*GL(30)*) Area 1775.8671 0.001 10000000 -1 1 MFWHM 1.822599 1.802599 1.822599 -1 1 Position 1383.0352 0 0 0 -3.9 RSF 0.817 MASS 28.0858 INDEX -1 (*Si 2p*) CONST (**)
CASA comp (*Si 2p Si2O*) (*GL(30)*) Area 3.4303159 0.001 10000000 -1 1 MFWHM 1.822599 0.24858463 6.2146156 3 1 Position 1385.9852 0 0 0 -0.95 RSF 0.817 MASS 28.0858 INDEX -1 (*Si 2p*) CONST (**)
XPS
0
Al
1486.6
1e+037
1e+037
1e+037
1e+037
1e+037
FAT
1e+037
1e+037
1e+037
1e+037
1e+037
1e+037
1e+037
1e+037
Si2p

-1
Binding Energy
eV
110
-0.1
1
Counts
d
pulse counting
1
1
1e+037
1e+037
1e+037
1e+037
2
MFP Exponent
d
0
PROPAGATION_CONVERGED
d
1
161
0
1
232.086
232.27
239.944
222.08
283.446
302.086
252.326
255.964
250.026
245.682
200.758
285.136
226.228
222.054
253.89
241.998
210.302
250.04
251.98
261.602
228.454
247.694
254.04
234.088
221.752
210.216
211.91
233.92
208.086
210.35
227.622
202.262
233.506
204.566
245.736
213.968
234.424
267.17
200.322
209.802
200.474
225.912
238.06
252.312
271.656
268.156
277.816
273.656
270.998
341.944
388.714
465.586
507.792
504.924
598.006
701.796
750.338
781.778
882.036
934.31
988.532
1052.95
960.284
1108.1
1057.93
1036.64
1072.53
960.832
1023.11
920.108
860.338
829.148
712.454
722.54
693.23
596.676
615.438
537.636
524.606
549.248
483.736
464.29
462.056
379.914
358.596
403.998
424.182
475.434
406.372
480.434
587.906
638.316
751.14
959.796
1214.69
1450.28
1725.39
1998.75
2144.94
2336.28
2534.54
2582.38
2743.82
2588.46
2539.7
2249.54
1849.4
1280.62
913.892
560.276
334.318
241.772
197.997
122.395
135.551
136.06
94.034
90.0512
84.1904
90.1846
113.628
78.4346
93.8466
81.8296
68.125
74.0796
101.761
77.9488
102.176
86.2244
101.733
71.9518
86.2954
93.8324
93.7414
78.1336
76.054
91.6478
98.1676
64.3608
99.7046
92.0568
76.0454
70.2272
83.9546
91.8664
76
62.1222
55.9034
85.7556
96.0824
90.0426
96.0852
75.983
86.1876
95.6904
64.2472
83.8324
76.267
101.795
93.767
Nb3d
L2822-6
0
0
0
0
0
0
0
11
Casa Info Follows
0
0
1
CASA region (*Nb 3d*) (*U 2 Tougaard*) 1274.8416 1286.2062 8.21 2 0 0 2399.7391 -650 0 0 (*Nb 3d*) 92.9064 0
4
CASA comp (*Nb-Nb 3d5/2*) (*LA(1,3,5)*) Area 0.001 0.001 10000000 -1 1 MFWHM 0.2 0.2 5 -1 1 Position 1289.974 1269.974 1289.974 -1 1 RSF 8.21 MASS 92.9064 INDEX -1 (*Nb 3d5/2*) CONST (**)
CASA comp (*Nb-Nb 3d3/2*) (*LA(1,3,5)*) Area 0.00067 0.001 10000000 0 0.67 MFWHM 0.2 0.2 5 0 1 Position 1287.254 0 0 0 -2.72 RSF 8.21 MASS 92.9064 INDEX -1 (*Nb 3d3/2*) CONST (**)
CASA comp (*Nb-Si 3d5/2*) (*LA(1,3,5)*) Area 28.881777 0.001 10000000 -1 1 MFWHM 0.11599506 0.089704905 2.2426226 -1 1 Position 1283.4752 1269.974 1289.974 -1 1 RSF 8.21 MASS 92.9064 INDEX -1 (*Nb 3d5/2*) CONST (**)
CASA comp (*Nb-Si 3d3/2*) (*LA(1,3,5)*) Area 19.350791 0.001 10000000 2 0.67 MFWHM 0.11599506 0.089704905 2.2426226 2 1 Position 1280.7552 0 0 2 -2.72 RSF 8.21 MASS 92.9064 INDEX -1 (*Nb 3d3/2*) CONST (**)
d:\yugin\demchenko\casaxps\l2822-6\01.vms
XPS
1
Al
1486.6
1e+037
1e+037
1e+037
1e+037
1e+037
FAT
1e+037
1e+037
1e+037
1e+037
1e+037
1e+037
1e+037
1e+037
Nb3d

-1
Binding Energy
eV
217
-0.1
1
Counts
d
pulse counting
1
1
1e+037
1e+037
1e+037
1e+037
2
MFP Exponent
d
0
PROPAGATION_CONVERGED
d
1
201
0
1
705.744
710.987
765.004
760.644
772.697
703.068
756.305
779.992
734.015
732.176
753.411
787.455
739.671
703.337
748.969
710.915
764.635
712.464
718.697
728.847
710.492
767.227
781.019
729.976
746.491
729.652
765.167
761.044
729.544
764.848
697.076
740.896
728.909
745.567
757.708
756.148
761.032
754.432
753.208
757.703
748.247
766.116
702.136
745.884
739.891
724.243
783.572
736.443
744.139
743.824
730.632
729.436
758.311
731.775
761.487
730.848
697.621
746.472
712.325
732.089
754.785
780.884
758.965
781.159
752.139
773.239
737.279
747.704
739.796
748.263
722.229
777.604
736.332
769.368
766.661
744.771
735.583
767.253
737.095
750.987
745.688
803.688
749.837
763.512
794.077
707.577
760.869
740.917
747.121
779.945
782.707
727.512
789.028
805.459
793.947
751.212
794.711
777.557
780.652
745.917
750.753
750.428
726.388
706.616
725.135
741.717
752.635
802.067
777.315
759.032
769.221
816.769
784.648
751.553
761.788
826.049
817.161
850.181
743.652
800.551
731.449
739.563
725.612
744.384
838.121
814.371
767.081
763.947
747.015
791.297
749.879
778.693
814.409
795.988
829.117
803.413
845.203
827.627
869.267
910.095
817.595
792.445
807.829
797.415
784.549
795.263
710.297
780.915
797.491
780.988
781.581
815.571
766.749
786.591
734.901
741.496
772.951
728.671
787.383
805.067
709.012
830.536
754.288
820.352
734.216
775.979
792.216
810.319
750.868
788.923
792.269
765.555
809.085
790.907
792.936
753.368
770.549
699.567
812.629
800.94
782.324
802.203
764.915
723.855
829.103
821.904
749.411
782.044
794.14
719.985
749.216
739.699
742.123
779.549
724.059
800.712
738.237
798.197
736.661
813.715
810.269
O1s
L2822-6
0
0
0
0
0
0
0
6
Casa Info Follows
0
0
0
0
d:\yugin\demchenko\casaxps\l2822-6\01.vms
XPS
1
Al
1486.6
1e+037
1e+037
1e+037
1e+037
1e+037
FAT
1e+037
1e+037
1e+037
1e+037
1e+037
1e+037
1e+037
1e+037
O1s

-1
Binding Energy
eV
541
-0.1
1
Counts
d
pulse counting
1
1
1e+037
1e+037
1e+037
1e+037
1
MFP Exponent
d
0
161
0
1
757.81
706.708
789.768
779.608
732.802
849.306
814.674
817.374
731
762.968
775.6
762.634
787.934
796.364
821.764
812.758
781.276
771.25
850.46
813.912
818.938
685.196
790.358
760.434
767.656
813.664
792.698
796.228
785.366
847.356
754.628
821.208
776.156
804.19
822.904
673.85
848.89
716.628
737.986
752.06
748.27
783.574
752.44
765.802
770.012
745.392
718.17
782.022
700.832
805.002
802.144
766.616
755.968
853.208
749.356
813.478
791.628
818.042
761.634
741.028
792.478
875.096
832.73
905.306
932.532
1000.09
1000.51
1093.07
1194.13
1384.58
1487.99
1623.82
1804.76
1988.69
2259.74
2399.4
2595.14
2853.16
3066.44
3336.4
3515.08
3585.28
3475.3
3613.26
3864.18
3393.16
3493.1
3306.94
3219.68
2955.96
2691.76
2502.02
2430.02
2103.8
1776.68
1654
1528.49
1235.26
1085.77
1073.64
989.376
871.338
826.39
888.002
874.298
800.384
756.318
809.378
748.258
704.094
688.322
769.676
718.224
755.432
710.752
720.258
713.642
741.182
694.568
650.448
719.764
679.938
703.11
664.44
721.84
731.568
692.934
673.944
690.062
721.778
664.684
773.448
779.222
692.952
705.028
692.822
736.424
714.708
800.522
733.33
642.79
708.238
697.844
614.196
703.732
715.414
708.48
690.276
724.188
703.83
695.84
703.986
733.322
609.278
765.358
769.778
716.106
643.822
632.256
674.864
755.17
Si2p
L2822-6
0
0
0
0
0
0
0
12
Casa Info Follows
0
0
1
CASA region (*Si 2p*) (*U 2 Tougaard*) 1380.4771 1389.0147 0.817 2 0 0 2512.3351 -650 0 0 (*Si 2p*) 28.0858 0
5
CASA comp (*Si 2p 3/2*) (*LA(1,1.5,250)*) Area 2604.505 0.001 10000000 -1 1 MFWHM 0.79170163 0.79170163 0.81170163 -1 1 Position 1386.9455 1386.9255 1386.9455 -1 1 RSF 0.817 MASS 28.0858 INDEX -1 (*Si 2p*) CONST (**)
CASA comp (*Si 2p 1/2*) (*LA(1,1.5,250)*) Area 1302.2525 0.001 10000000 0 0.5 MFWHM 0.79170163 0.24 6 0 1 Position 1386.3155 0 0 0 -0.63 RSF 0.817 MASS 28.0858 INDEX -1 (*Si 2p*) CONST (**)
CASA comp (*Si 2p Si2O3*) (*GL(30)*) Area 680.40885 0.001 10000000 -1 1 MFWHM 1.822599 0.24 6 3 1 Position 1384.4655 0 0 0 -2.48 RSF 0.817 MASS 28.0858 INDEX -1 (*Si 2p*) CONST (**)
CASA comp (*Si 2p SiO2*) (*GL(30)*) Area 755.45345 0.001 10000000 -1 1 MFWHM 1.822599 1.802599 1.822599 -1 1 Position 1383.0455 0 0 0 -3.9 RSF 0.817 MASS 28.0858 INDEX -1 (*Si 2p*) CONST (**)
CASA comp (*Si 2p Si2O*) (*GL(30)*) Area 607.97561 0.001 10000000 -1 1 MFWHM 1.822599 0.24858463 6.2146156 3 1 Position 1385.9955 0 0 0 -0.95 RSF 0.817 MASS 28.0858 INDEX -1 (*Si 2p*) CONST (**)
d:\yugin\demchenko\casaxps\l2822-6\01.vms
XPS
1
Al
1486.6
1e+037
1e+037
1e+037
1e+037
1e+037
FAT
1e+037
1e+037
1e+037
1e+037
1e+037
1e+037
1e+037
1e+037
Si2p

-1
Binding Energy
eV
110
-0.1
1
Counts
d
pulse counting
1
1
1e+037
1e+037
1e+037
1e+037
2
MFP Exponent
d
0
PROPAGATION_CONVERGED
d
1
161
0
1
270.198
272.222
303.312
260.344
293.548
282.532
305.852
286.304
310.364
417.116
296.508
365.464
318.14
301.722
286.184
295.85
294.498
319.926
300.018
275.684
242.526
287.9
289.804
288.312
289.634
272.302
286.082
311.322
248.52
325.198
232.684
291.566
231.008
265.654
257.352
250.718
323.594
295.764
266.426
269.92
247.926
262.142
231.944
248.144
303.48
252.336
276.27
289.562
276.194
319.772
274.306
272.258
344.27
358.41
397.718
391.958
437.676
453.978
500.23
518
532.54
605.856
591.784
617.546
612.444
669.75
721.938
684.21
698.506
743.34
674.164
666.474
677.694
678.258
709.938
708.14
687.982
695.978
691.752
659.748
592.06
584.312
611.772
655.786
642.386
702.886
740.424
823.134
778.136
789.926
976.532
1021.5
1241.16
1328.77
1673.42
1967.36
2211.72
2500.06
2774.4
2844.58
2893.68
3003.76
3107.02
3182.84
3033
2695.06
2088.52
1573.98
1106.01
696.298
503.772
310.59
267.804
175.963
153.997
138.216
138.156
117.844
108.099
98.1306
77.9262
81.7358
92.1164
105.881
79.963
76.1222
68.2216
87.7472
76
64.1108
60.0768
67.9488
67.9546
68.3268
89.733
86
83.8608
74.1676
71.9432
81.8806
86.0198
74.3352
95.4772
64.3836
80.0312
68.1278
87.733
80.125
90.054
89.963
78.0284
86.0938
103.526
68.2188
85.9744
95.7982
70.5852
91.6704
70.0596
63.8948
70.2472
Nb3d
L2822-6
0
0
0
0
0
0
0
11
Casa Info Follows
0
0
1
CASA region (*Nb 3d*) (*U 2 Tougaard*) 1274.8416 1286.2062 8.21 2 0 0 1718.4004 -650 0 0 (*Nb 3d*) 92.9064 0
4
CASA comp (*Nb-Nb 3d5/2*) (*LA(1,3,5)*) Area 0.001 0.001 10000000 -1 1 MFWHM 5 0.2 5 -1 1 Position 1289.974 1269.974 1289.974 -1 1 RSF 8.21 MASS 92.9064 INDEX -1 (*Nb 3d5/2*) CONST (**)
CASA comp (*Nb-Nb 3d3/2*) (*LA(1,3,5)*) Area 0.00067 0.001 10000000 0 0.67 MFWHM 5 0.2 5 0 1 Position 1287.254 0 0 0 -2.72 RSF 8.21 MASS 92.9064 INDEX -1 (*Nb 3d3/2*) CONST (**)
CASA comp (*Nb-Si 3d5/2*) (*LA(1,3,5)*) Area 692.50609 0.001 10000000 -1 1 MFWHM 0.67335626 0.089704905 2.2426226 -1 1 Position 1283.4534 1269.974 1289.974 -1 1 RSF 8.21 MASS 92.9064 INDEX -1 (*Nb 3d5/2*) CONST (**)
CASA comp (*Nb-Si 3d3/2*) (*LA(1,3,5)*) Area 463.97908 0.001 10000000 2 0.67 MFWHM 0.67335626 0.089704905 2.2426226 2 1 Position 1280.7334 0 0 2 -2.72 RSF 8.21 MASS 92.9064 INDEX -1 (*Nb 3d3/2*) CONST (**)
d:\yugin\demchenko\casaxps\l2822-6\08.vms
XPS
8
Al
1486.6
1e+037
1e+037
1e+037
1e+037
1e+037
FAT
1e+037
1e+037
1e+037
1e+037
1e+037
1e+037
1e+037
1e+037
Nb3d

-1
Binding Energy
eV
217
-0.1
1
Counts
d
pulse counting
1
1
1e+037
1e+037
1e+037
1e+037
2
MFP Exponent
d
0
PROPAGATION_CONVERGED
d
1
201
0
1
797.749
738.703
755.233
764.161
797.072
764.397
812.856
736.391
777.393
739.744
798.704
750.905
785.027
789.607
768.355
811.805
785.109
759.701
775.021
768.289
746.404
805.468
757.436
777.847
716.324
730.937
745.107
726.856
700.285
786.773
746.636
768.964
738.392
725.724
807.704
757.267
772.744
711.099
777.293
718.697
756.725
715.332
774.357
746.761
725.72
749.58
743.945
748.201
772.037
740.237
779.131
749.657
750.297
680.443
760.024
801.109
754.679
705.377
734.607
726.571
720.643
683.981
743.968
754.809
804.648
752.969
718.077
749.001
720.355
732.159
767.243
741.123
687.459
721.512
708.125
777.909
746.455
675.857
796.292
734.103
736.919
761.265
767.18
756.883
718.433
722.625
700.129
745.729
740.152
722.835
757.441
819.901
699.731
768.964
764.125
789.129
788.191
799.207
826.188
805.273
796.263
810.149
779.923
778.235
919.5
932.243
888.924
1006.48
1039.15
966.312
1138.65
1036.52
1027.14
927.005
897.455
895.368
847.059
781.623
782.771
815.481
759.297
812.629
756.396
793.337
786.063
805.861
812.108
807.785
823.067
842.621
857.42
832.288
902.171
981.616
996.508
1083.03
1240.54
1223.91
1184.11
1174.18
1165.74
981.427
945.123
888.064
847.779
783.883
763.515
732.684
752.383
782.216
774.811
730.864
765.897
726.868
686.315
732.963
756.955
762.652
761.541
753.243
754.019
695.239
747.063
682.001
708.416
685.172
735.581
681.964
741.773
727.044
776.737
731.883
806.143
690.463
755.749
702.267
723.023
828.517
778.981
782.397
746.629
761.067
678.596
655.284
737.581
778.256
738.067
722.707
710.913
716.593
751.783
734.884
761.419
749.161
755.731
775.36
773.729
667.125
765.237
754.289
712.564
O1s
L2822-6
0
0
0
0
0
0
0
6
Casa Info Follows
0
0
0
0
d:\yugin\demchenko\casaxps\l2822-6\08.vms
XPS
8
Al
1486.6
1e+037
1e+037
1e+037
1e+037
1e+037
FAT
1e+037
1e+037
1e+037
1e+037
1e+037
1e+037
1e+037
1e+037
O1s

-1
Binding Energy
eV
541
-0.1
1
Counts
d
pulse counting
1
1
1e+037
1e+037
1e+037
1e+037
1
MFP Exponent
d
0
161
0
1
744.98
680.768
782.898
706.94
749.696
787.748
703.12
802.856
710.284
736.832
813.602
737.736
697.894
709.864
806.108
700.46
720.458
763.636
815.148
670.9
761.026
756.286
742.244
755.432
746
726.52
733.89
746.278
710.33
695.786
719.454
728.404
721.548
738.16
768.04
789.792
731.69
712.622
737.736
768.068
682.208
700.174
723.71
725.048
725.526
768.528
814.364
707.082
676.17
727.776
680.512
763.636
721.86
750.91
656.81
712.238
723.622
701.218
754.87
738.052
747.952
767.904
714.216
687.534
652.556
769.508
718.832
743.508
733.898
682.642
804.986
686.6
718.446
769.174
708
746.398
697.636
780.1
771.63
740.17
808.298
825.748
801.79
803.738
818.83
812.64
817.394
797.858
902.44
893.998
851.946
958.162
844.08
998.682
928.406
878.81
908.974
811.85
830.194
760.946
779.674
723.708
726.83
843.486
763.534
748.526
775.114
716.196
669.144
788.906
716.418
726.188
789.56
765.668
716.89
789.312
710.33
708.286
779.498
730.894
854.056
733.21
778.552
720.56
797.052
720.662
719.978
721.142
710.216
691.87
720.222
797.222
720.198
752.37
851.826
754.792
793.006
720.232
763.386
685.228
689.786
749.784
744.508
743.678
691.656
767.798
795.674
732.256
720.412
725.724
793.94
797.994
751.796
732.232
718.446
805.36
788.372
795.83
744.244
740.568
815.196
Si2p
L2822-6
0
0
0
0
0
0
0
10
Casa Info Follows
0
0
1
CASA region (*Si 2p*) (*U 2 Tougaard*) 1382.3834 1388.9007 0.817 2 0 0 2825.808 -650 0 0 (*Si 2p*) 28.0858 0
3
CASA comp (*Si 2p*) (*LA(1,1.5,250)*) Area 5459.543 0.001 10000000 -1 1 MFWHM 0.9 0.7 0.9 -1 1 Position 1386.8933 1386.543 1387.143 -1 1 RSF 0.817 MASS 28.0858 INDEX -1 (*Si 2p*) CONST (**)
CASA comp (*Si-Nb*) (*LA(1,1.5,250)*) Area 246.56151 0.001 10000000 -1 1 MFWHM 0.9 0.24 6 0 1 Position 1387.4492 1387.4492 1388.0492 -1 1 RSF 0.817 MASS 28.0858 INDEX -1 (*Si 2p*) CONST (**)
CASA comp (*Si 2p SiOx*) (*GL(30)*) Area 138.09571 138.07571 138.09571 -1 1 MFWHM 0.9 1.46 1.48 0 1 Position 1386.32 1386.32 1386.34 -1 -0.95 RSF 0.817 MASS 28.0858 INDEX -1 (*Si 2p*) CONST (**)
d:\yugin\demchenko\casaxps\l2822-6\08.vms
XPS
8
Al
1486.6
1e+037
1e+037
1e+037
1e+037
1e+037
FAT
1e+037
1e+037
1e+037
1e+037
1e+037
1e+037
1e+037
1e+037
Si2p

-1
Binding Energy
eV
110
-0.1
1
Counts
d
pulse counting
1
1
1e+037
1e+037
1e+037
1e+037
2
MFP Exponent
d
0
PROPAGATION_CONVERGED
d
1
161
0
1
439.738
423.756
404.228
417.352
360.568
367.988
368.076
346.466
433.554
409.822
399.756
382.014
363.728
365.786
291.296
393.44
327.886
335.894
327.768
330.106
332.162
349.864
302.31
330.054
330.144
354.008
299.364
323.52
312.872
326.392
335.488
250.394
329.292
298.782
321.786
329.696
354.094
339.758
294.65
363.236
302.12
301.752
320.674
272.156
283.514
324.136
341.582
280.338
272.66
315.154
262.028
264.238
286.036
283.81
282.262
301.714
296.448
341.644
285.864
246.606
301.42
272.338
291.664
264.418
289.878
297.778
286.326
277.492
290.106
270.16
303.892
319.86
302.034
250.404
285.678
260.668
285.38
270.066
279.796
305.696
286.532
321.65
272.526
267.802
317.622
306.668
350.41
394.398
463.66
489.202
620.306
756.876
1022.38
1391.7
1750.44
2248.88
2903.58
3201.8
3796.08
4013.94
4304.28
4437.52
4820.8
5170.82
4996.6
4266.7
3758.5
2952.12
2009.58
1383.54
824.472
510.804
389.778
283.92
259.934
210.052
126.429
143.884
139.869
126.051
114.06
125.983
114.372
129.503
126.034
120.097
131.645
96.3636
112
121.872
130.054
131.974
118.128
108.205
113.753
88.0482
101.804
106.011
92.2982
125.872
127.73
90.6392
153.597
111.881
105.952
86.2472
103.483
80.4886
92.341
125.406
88.0852
107.997
112.011
136.134
123.915
116.065
97.892
86.4488
117.389
70.6762
127.287
Nb3d
L2822-6
0
0
0
0
0
0
0
11
Casa Info Follows
0
0
1
CASA region (*Nb 3d*) (*U 2 Tougaard*) 1274.8416 1286.2062 8.21 2 0 0 2432.5545 -650 0 0 (*Nb 3d*) 92.9064 0
4
CASA comp (*Nb-Nb 3d5/2*) (*LA(1,3,5)*) Area 6.7067882 0.001 10000000 -1 1 MFWHM 0.59575305 0.2 5 -1 1 Position 1286.1854 1269.974 1289.974 -1 1 RSF 8.21 MASS 92.9064 INDEX -1 (*Nb 3d5/2*) CONST (**)
CASA comp (*Nb-Nb 3d3/2*) (*LA(1,3,5)*) Area 4.4935481 0.001 10000000 0 0.67 MFWHM 0.59575305 0.2 5 0 1 Position 1283.4654 0 0 0 -2.72 RSF 8.21 MASS 92.9064 INDEX -1 (*Nb 3d3/2*) CONST (**)
CASA comp (*Nb-Si 3d5/2*) (*LA(1,3,5)*) Area 4819.0146 0.001 10000000 -1 1 MFWHM 0.57602943 0.089704905 2.2426226 -1 1 Position 1283.4507 1269.974 1289.974 -1 1 RSF 8.21 MASS 92.9064 INDEX -1 (*Nb 3d5/2*) CONST (**)
CASA comp (*Nb-Si 3d3/2*) (*LA(1,3,5)*) Area 3228.7398 0.001 10000000 2 0.67 MFWHM 0.57602943 0.089704905 2.2426226 2 1 Position 1280.7307 0 0 2 -2.72 RSF 8.21 MASS 92.9064 INDEX -1 (*Nb 3d3/2*) CONST (**)
d:\yugin\demchenko\casaxps\l2822-6\14.vms
XPS
14
Al
1486.6
1e+037
1e+037
1e+037
1e+037
1e+037
FAT
1e+037
1e+037
1e+037
1e+037
1e+037
1e+037
1e+037
1e+037
Nb3d

-1
Binding Energy
eV
217
-0.1
1
Counts
d
pulse counting
1
1
1e+037
1e+037
1e+037
1e+037
2
MFP Exponent
d
0
PROPAGATION_CONVERGED
d
1
201
0
1
1091.63
1133.58
1088.43
1063.07
1069.52
1071.08
1034.01
1046.92
1130.84
1108.5
1097.79
1063.22
1118.58
1025.83
1053.3
1065.23
1031.39
947.191
1070.58
1073.38
1025.06
963.943
1049.38
1014.02
1045.69
954.021
948.688
962.347
1015.35
1013.22
984.564
1008.62
976.505
987.845
998.557
1007.69
986.753
989.191
941.483
933.616
965.992
939.405
1004.92
903.252
980.329
914.387
977.099
990.424
962.995
927.483
947.923
938
960.095
922.267
892.204
981.319
875.976
900.955
917.917
965.329
941.145
919.715
910.464
924.211
931.073
885.019
931.92
917.071
898.531
919.973
877.161
935.708
894.877
953.195
855.26
931.913
931.396
965.392
1025.9
967.104
948.528
972.883
1000.07
944.081
963.661
1019.16
960.568
948.819
989.123
1022.2
988.841
1066.18
1060.16
1130.54
1032.67
1107.78
1124.74
1200.48
1242.13
1239.87
1354.6
1349.39
1463.53
1658.51
1817.52
2076.84
2407.03
2570.33
2986.56
3162.19
3246.24
3280.36
3175.29
2642.35
2200.79
1952.64
1616.55
1467.37
1277.72
1213.82
1181.4
1187.78
1124.63
1087.61
1119.69
1108.33
1157.33
1219.2
1323.39
1441.72
1654.79
1762.83
2189.97
2558.05
3063.17
3679.67
4421.92
4853.52
4845.76
4447.04
3915.85
3147.51
2226.91
1700.63
1265.8
1010.63
822.188
778.5
782.407
721.725
706.964
730.212
647.675
762.535
672.809
712.015
703.279
729.753
685.617
718.201
657.892
678.221
638.733
624.163
622.731
621.868
636.144
680.048
630.012
634.888
670.6
680.049
648.256
625.093
691.536
673.731
671.419
589.148
667.828
672.747
631.055
664.144
641.717
698.204
683.763
681.564
670.099
627.217
611.377
584.591
627.676
576.661
663.869
611.072
657.384
662.609
600.443
658.701
613.521
644.316
618.171
O1s
L2822-6
0
0
0
0
0
0
0
6
Casa Info Follows
0
0
0
0
d:\yugin\demchenko\casaxps\l2822-6\14.vms
XPS
14
Al
1486.6
1e+037
1e+037
1e+037
1e+037
1e+037
FAT
1e+037
1e+037
1e+037
1e+037
1e+037
1e+037
1e+037
1e+037
O1s

-1
Binding Energy
eV
541
-0.1
1
Counts
d
pulse counting
1
1
1e+037
1e+037
1e+037
1e+037
1
MFP Exponent
d
0
161
0
1
651.676
696.04
641.71
644.634
668.322
735.482
710.136
755.31
708.054
676.52
677.974
700.036
690.616
703.87
695.258
652.228
714.002
690.188
647.816
652.08
672.216
629.338
748.322
719.758
700.874
733.5
761.488
706.668
697.84
747.938
682.392
766.906
661.346
727.028
725.664
646.48
683.96
677.546
599.242
678.042
703.486
680.844
704.46
587.258
681.366
698.046
697.928
684.25
665.92
647.838
670.46
689.576
689.822
674.852
762.428
614.458
686.316
685.736
680.39
773.522
626.724
695.44
725.704
672.648
690.16
713.424
713.702
664.664
712.11
711.812
698.804
772.552
662.9
691.434
691.968
696.428
694.048
706.262
717.822
785.048
685.582
814.876
730.438
783.852
736.644
779.364
779.568
750.216
764.644
780.468
867.84
862.028
923.768
787.9
822.114
821.844
790.5
785.488
792.1
769.986
823.542
730.04
741.542
694.512
760.032
741.48
629.178
727.108
723.698
753.162
638.804
711.884
664.268
710.06
696.142
696.318
714.356
717.728
676.162
722.204
731.036
652.488
696.216
719.428
735.628
694.62
775.836
716.458
747.278
690.346
737.576
746.748
766.018
745.14
673.75
734.322
683.718
768.586
805.926
727.714
680.778
706.094
697.744
730.386
777.312
690.662
688.076
728.926
701.986
701.276
699.472
684.062
689.424
686.34
735.98
704.318
753.678
712.5
741.702
691.992
733.662
Si2p
L2822-6
0
0
0
0
0
0
0
10
Casa Info Follows
0
0
1
CASA region (*Si 2p*) (*U 2 Tougaard*) 1382.3834 1388.9007 0.817 2 0 0 2666.351 -650 0 0 (*Si 2p*) 28.0858 0
3
CASA comp (*Si 2p*) (*LA(1,1.5,250)*) Area 4871.2551 0.001 10000000 -1 1 MFWHM 0.9 0.7 0.9 -1 1 Position 1386.8532 1386.543 1387.143 -1 1 RSF 0.817 MASS 28.0858 INDEX -1 (*Si 2p*) CONST (**)
CASA comp (*Si-Nb*) (*LA(1,1.5,250)*) Area 502.9087 0.001 10000000 -1 1 MFWHM 0.9 0.24 6 0 1 Position 1387.4492 1387.4492 1388.0492 -1 1 RSF 0.817 MASS 28.0858 INDEX -1 (*Si 2p*) CONST (**)
CASA comp (*Si 2p SiOx*) (*GL(30)*) Area 138.09571 138.07571 138.09571 -1 1 MFWHM 0.9 1.46 1.48 0 1 Position 1386.32 1386.32 1386.34 -1 -0.95 RSF 0.817 MASS 28.0858 INDEX -1 (*Si 2p*) CONST (**)
d:\yugin\demchenko\casaxps\l2822-6\14.vms
XPS
14
Al
1486.6
1e+037
1e+037
1e+037
1e+037
1e+037
FAT
1e+037
1e+037
1e+037
1e+037
1e+037
1e+037
1e+037
1e+037
Si2p

-1
Binding Energy
eV
110
-0.1
1
Counts
d
pulse counting
1
1
1e+037
1e+037
1e+037
1e+037
2
MFP Exponent
d
0
PROPAGATION_CONVERGED
d
1
161
0
1
351.174
342.014
308.358
349.688
329.844
302.214
309.566
292.772
311.804
274.164
339.852
351.894
329.724
320.474
333.108
235.072
313.406
274.438
327.418
305.994
274.38
291.542
266.242
290.326
285.738
270.36
276.144
307.596
289.98
260.572
301.616
301.772
304.106
315.898
292.222
269.872
281.858
260.4
311.668
268.566
303.204
252.912
301.296
291.968
261.944
275.914
270.214
261.96
241.892
258.608
297.602
268.472
309.33
291.892
283.874
260.316
260.074
280.534
289.478
274.232
278.208
287.62
264.292
297.232
306.438
321.278
266.662
293.906
236.536
277.616
317.978
291.818
264.42
269.588
270.41
282.264
347.216
274.124
296.056
302.514
353.542
306.184
321.94
342.14
370.866
461.534
449.718
418.656
514.208
610.106
585.556
877.606
971.62
1283.07
1644
1966.61
2483.04
2896.9
3221.36
3489.46
3762.12
3917.24
4305.16
4434.88
4304.82
4036.16
3448.22
2736.02
1972.39
1436.9
879.398
547.518
360.198
270.286
235.812
202.014
168.253
179.531
166.241
134.318
169.403
145.952
132.173
139.972
142.219
132.179
138.034
169.753
125.807
136.287
135.824
129.915
94.2982
112.065
122.08
159.531
110.557
133.534
96.5426
145.528
122.031
133.798
132.063
127.827
108.42
128.06
149.753
126.33
135.679
110.091
111.798
97.9972
99.892
116.321
114.443
143.398
90.2614
124.071
127.892
106.125
129.892
Nb3d
L2822-6
0
0
0
0
0
0
0
11
Casa Info Follows
0
0
1
CASA region (*Nb 3d*) (*U 2 Tougaard*) 1274.8416 1286.2062 8.21 2 0 0 2272.1822 -650 0 0 (*Nb 3d*) 92.9064 0
4
CASA comp (*Nb-Nb 3d5/2*) (*LA(1,3,5)*) Area 0.001 0.001 10000000 -1 1 MFWHM 5 0.2 5 -1 1 Position 1285.2276 1269.974 1289.974 -1 1 RSF 8.21 MASS 92.9064 INDEX -1 (*Nb 3d5/2*) CONST (**)
CASA comp (*Nb-Nb 3d3/2*) (*LA(1,3,5)*) Area 0.00067 0.001 10000000 0 0.67 MFWHM 5 0.2 5 0 1 Position 1282.5076 0 0 0 -2.72 RSF 8.21 MASS 92.9064 INDEX -1 (*Nb 3d3/2*) CONST (**)
CASA comp (*Nb-Si 3d5/2*) (*LA(1,3,5)*) Area 8961.1396 0.001 10000000 -1 1 MFWHM 0.58603752 0.089704905 2.2426226 -1 1 Position 1283.4041 1269.974 1289.974 -1 1 RSF 8.21 MASS 92.9064 INDEX -1 (*Nb 3d5/2*) CONST (**)
CASA comp (*Nb-Si 3d3/2*) (*LA(1,3,5)*) Area 6003.9635 0.001 10000000 2 0.67 MFWHM 0.58603752 0.089704905 2.2426226 2 1 Position 1280.6841 0 0 2 -2.72 RSF 8.21 MASS 92.9064 INDEX -1 (*Nb 3d3/2*) CONST (**)
d:\yugin\demchenko\casaxps\l2822-6\17.vms
XPS
17
Al
1486.6
1e+037
1e+037
1e+037
1e+037
1e+037
FAT
1e+037
1e+037
1e+037
1e+037
1e+037
1e+037
1e+037
1e+037
Nb3d

-1
Binding Energy
eV
217
-0.1
1
Counts
d
pulse counting
1
1
1e+037
1e+037
1e+037
1e+037
2
MFP Exponent
d
0
PROPAGATION_CONVERGED
d
1
201
0
1
1224.87
1254.84
1209.72
1284.62
1196.38
1215.4
1178.09
1239.14
1134.04
1200.74
1205.89
1200.61
1109.59
1153.65
1157.33
1100.21
1158.79
1191.57
1149.44
1139.58
1113.77
1168.61
1119.24
1095.73
1173.46
1145.47
1108
1114.19
1048.02
1080.43
1109.92
1119.64
1076.91
1135.81
1081.78
1150.54
1071.87
1146.01
1069.56
1085.53
1115.53
1037.07
1130.5
1140.18
1117.02
1116.71
1034.09
1080.58
1110.22
1126.59
1100.6
1111.39
1093.14
1105.24
1055.66
1056.7
1050.24
1085.66
1106.27
1083.86
1086.5
1092.37
1087.38
1087.64
1116.34
1067.4
1161.5
1051.24
1158.71
1116.28
1135.35
1150.25
1110.73
1095.33
1191.03
1147.46
1194.76
1146.62
1198.42
1160.58
1249.6
1174.54
1204.91
1256.79
1213.67
1210.19
1261.97
1299.38
1346.39
1393.52
1460.81
1353.27
1349.45
1369.68
1409.29
1447
1600.17
1655.57
1847.68
1842.92
1973.65
2234.91
2353.09
2729.11
2966.33
3406.52
3881.07
4408.07
4993.72
5366.72
5301.37
5385.59
4629.25
3847.32
3232.69
2710.79
2170.21
1936.32
1706.59
1570.48
1482.08
1546.13
1508.72
1611.08
1655.15
1644.43
1790.07
1886.47
2035.83
2324.44
2572
3038.92
3721.75
4697.95
5770.08
6598.09
7781.77
8341.73
8265.25
7461.27
6020.55
4393.76
3010.75
2005.2
1465.93
1162.65
1028.95
958.964
800.401
739.207
756.144
747.855
717.456
692.001
643.032
648.747
645.037
637.76
704.965
652.501
657.32
637.073
662.773
687.612
646.861
645.429
569.799
590.037
587.311
667.392
588.267
613.235
638.621
633.332
608.123
654.463
655.067
662.119
610.009
673.143
649.409
666.485
631.233
611.263
647.864
636.26
615.021
642.429
600.024
604
612.816
603.084
624.307
633.215
610.819
607.008
633.875
608.297
640.881
623.812
606.072
O1s
L2822-6
0
0
0
0
0
0
0
6
Casa Info Follows
0
0
0
0
d:\yugin\demchenko\casaxps\l2822-6\17.vms
XPS
17
Al
1486.6
1e+037
1e+037
1e+037
1e+037
1e+037
FAT
1e+037
1e+037
1e+037
1e+037
1e+037
1e+037
1e+037
1e+037
O1s

-1
Binding Energy
eV
541
-0.1
1
Counts
d
pulse counting
1
1
1e+037
1e+037
1e+037
1e+037
1
MFP Exponent
d
0
161
0
1
591.494
585.492
520.75
661.042
588.244
546.466
585.79
606.9
671.184
554.86
581.552
577.866
534.256
617.9
601.992
536.48
635.44
564.034
552.448
623.352
584.298
612.236
591.704
588.122
593.982
536.14
549.768
575.608
540.776
605.438
638.014
613.84
557.884
568.878
576.528
642.866
607.698
604.494
653.222
574.5
586.452
651.398
582.596
591.23
528.466
621.992
610.282
568.136
573.874
663.69
619.682
615.858
554.978
639.634
593.798
586.96
655.364
631.418
586.778
628.048
614.13
625.86
621.822
618.072
616.296
653.25
568.198
616.11
609.21
568.244
578.586
589.31
538.696
597.772
628.002
625.812
600.236
625.71
580.116
558.33
593.784
627.86
592.238
571.636
583.998
570.654
607.978
623.278
600.048
653.548
689.498
589.268
633.802
611.858
656.34
658.062
643.256
594.722
663.398
615.046
661.11
579.21
698.972
650.634
650.106
667.258
669.914
590.434
568.116
629.886
604.674
651.04
590.198
644.006
626.332
595.986
598.02
609.292
564.478
631.624
576.134
568.178
563.926
595.73
603.014
624.262
681.798
637.426
650.006
665.256
537.042
629.38
622.684
643.866
659.608
619.11
624.1
679.096
649.732
631.276
616.248
603.1
637.616
625.732
663.296
600.364
576.35
613.768
588.514
615.9
633.986
619.582
570.022
590.052
593.77
667.838
630.338
649.852
642.086
618.108
611.062
Si2p
L2822-6
0
0
0
0
0
0
0
10
Casa Info Follows
0
0
1
CASA region (*Si 2p*) (*U 2 Tougaard*) 1382.3834 1388.9007 0.817 2 0 0 3325.3627 -650 0 0 (*Si 2p*) 28.0858 0
3
CASA comp (*Si 2p*) (*LA(1,1.5,250)*) Area 3857.2439 0.001 10000000 -1 1 MFWHM 0.9 0.7 0.9 -1 1 Position 1386.8627 1386.543 1387.143 -1 1 RSF 0.817 MASS 28.0858 INDEX -1 (*Si 2p*) CONST (**)
CASA comp (*Si-Nb*) (*LA(1,1.5,250)*) Area 546.03011 0.001 10000000 -1 1 MFWHM 0.9 0.24 6 0 1 Position 1387.4492 1387.4492 1388.0492 -1 1 RSF 0.817 MASS 28.0858 INDEX -1 (*Si 2p*) CONST (**)
CASA comp (*Si 2p SiOx*) (*GL(30)*) Area 138.09571 138.07571 138.09571 -1 1 MFWHM 0.9 1.46 1.48 0 1 Position 1386.32 1386.32 1386.34 -1 -0.95 RSF 0.817 MASS 28.0858 INDEX -1 (*Si 2p*) CONST (**)
d:\yugin\demchenko\casaxps\l2822-6\17.vms
XPS
17
Al
1486.6
1e+037
1e+037
1e+037
1e+037
1e+037
FAT
1e+037
1e+037
1e+037
1e+037
1e+037
1e+037
1e+037
1e+037
Si2p

-1
Binding Energy
eV
110
-0.1
1
Counts
d
pulse counting
1
1
1e+037
1e+037
1e+037
1e+037
2
MFP Exponent
d
0
PROPAGATION_CONVERGED
d
1
161
0
1
232.404
275.394
241.728
258.472
253.532
222.096
234.028
240.176
283.468
242.322
244.306
249.588
238.21
226.244
247.736
266.452
259.322
220.08
261.836
250.424
269.94
239.654
253.84
222.228
243.806
218.626
221.81
222.324
273.812
255.464
258.16
244.062
251.698
206.154
225.994
265.486
214.702
207.914
192.199
276.018
255.526
204.732
263.91
275.86
262.232
269.668
234.262
246.268
245.526
204.072
259.914
236.062
238.034
220.13
281.81
237.846
241.948
252.174
253.886
246.27
236.04
285.514
238.16
221.964
241.81
208.346
240.272
261.434
242.608
266.184
228.122
289.268
232.19
245.914
218.386
281.268
244.528
265.992
272.14
251.816
296.042
273.98
276.256
307.892
312.356
350.108
378.034
418.238
444.162
482.218
581.876
660.428
783.068
930.27
1137.54
1599.99
1867.54
2110.82
2441
2890.78
3035.72
3408.02
3372.24
3647.7
3424.1
3366.42
3014.26
2427.12
1796.19
1260.03
810.204
488.694
355.954
261.978
200.06
136.389
159.71
156.207
130.091
127.923
139.983
121.963
92.2698
117.554
94.4432
119.83
98.0966
111.912
109.952
90.0568
119.793
102.318
128.074
133.432
80.5852
113.733
108.003
119.628
92.1988
98.2244
104.153
117.685
128.239
105.906
89.9176
82.1648
101.821
100.284
145.469
112.327
118.094
119.886
109.852
90.5568
121.659
117.923
104.062
68.3466
151.574
100.136
118.207
Nb3d
L2822-6
0
0
0
0
0
0
0
11
Casa Info Follows
0
0
1
CASA region (*Nb 3d*) (*U 2 Tougaard*) 1274.8416 1286.2062 8.21 2 0 0 2014.6514 -650 0 0 (*Nb 3d*) 92.9064 0
4
CASA comp (*Nb-Nb 3d5/2*) (*LA(1,3,5)*) Area 0.001 0.001 10000000 -1 1 MFWHM 0.2 0.2 5 -1 1 Position 1289.974 1269.974 1289.974 -1 1 RSF 8.21 MASS 92.9064 INDEX -1 (*Nb 3d5/2*) CONST (**)
CASA comp (*Nb-Nb 3d3/2*) (*LA(1,3,5)*) Area 0.00067 0.001 10000000 0 0.67 MFWHM 0.2 0.2 5 0 1 Position 1287.254 0 0 0 -2.72 RSF 8.21 MASS 92.9064 INDEX -1 (*Nb 3d3/2*) CONST (**)
CASA comp (*Nb-Si 3d5/2*) (*LA(1,3,5)*) Area 5957.7785 0.001 10000000 -1 1 MFWHM 0.5920155 0.089704905 2.2426226 -1 1 Position 1283.4182 1269.974 1289.974 -1 1 RSF 8.21 MASS 92.9064 INDEX -1 (*Nb 3d5/2*) CONST (**)
CASA comp (*Nb-Si 3d3/2*) (*LA(1,3,5)*) Area 3991.7116 0.001 10000000 2 0.67 MFWHM 0.5920155 0.089704905 2.2426226 2 1 Position 1280.6982 0 0 2 -2.72 RSF 8.21 MASS 92.9064 INDEX -1 (*Nb 3d3/2*) CONST (**)
d:\yugin\demchenko\casaxps\l2822-6\24.vms
XPS
24
Al
1486.6
1e+037
1e+037
1e+037
1e+037
1e+037
FAT
1e+037
1e+037
1e+037
1e+037
1e+037
1e+037
1e+037
1e+037
Nb3d

-1
Binding Energy
eV
217
-0.1
1
Counts
d
pulse counting
1
1
1e+037
1e+037
1e+037
1e+037
2
MFP Exponent
d
0
PROPAGATION_CONVERGED
d
1
201
0
1
822.113
894.283
891.715
919.167
934.393
880.207
873.081
917.123
929.465
872.045
830.405
909.635
856.377
843.76
883.837
824.428
879.157
827.032
805.504
852.125
847.329
870.711
846.743
865.54
906.959
861.721
776.985
856.607
781.368
779.387
870.132
821.963
884.532
845.504
908.424
779.513
776.191
803.805
780.888
783.121
804.855
774.655
832.312
806.851
804.652
864.415
843.744
814.968
743.649
819.752
806.685
767.639
809.577
791.512
849.208
787.084
817.963
784.464
791.216
767.031
854.204
837.328
833.203
761.329
762.927
826.332
806.653
821.091
800.121
839.632
843.517
878
816.469
864.048
856.107
839.64
847.784
828.076
828.049
891.636
860.743
863.672
884.129
878.021
969.635
879.428
913.083
902.567
946.915
966.785
915.663
1006.1
1019.63
1020.43
1073.36
1125.32
1165.39
1227.22
1229.67
1364.19
1493.49
1480.21
1602.97
1830.71
2131.97
2390.69
2817.03
3030.25
3395.56
3594.47
3626.73
3596.28
3283.03
2824.21
2365.24
1962.6
1614.73
1352.39
1232.2
1153.4
1142.96
1114.82
1092.04
1156.31
1146.54
1168.2
1222.95
1380.39
1434.64
1617.92
1926.91
2078.67
2563.37
3205.84
3821.64
4558.6
5310.85
5561.05
5554.93
5099.88
4203.96
3275.83
2409.53
1622.77
1179.82
882.833
782.737
699.063
665.008
573.963
634.273
572.315
561.108
513.347
551.707
548.089
558.735
538.004
475.184
512.483
531.345
505.535
495.355
565.976
537.881
536.095
524.972
555.833
522.681
553.936
480.829
544.143
513.747
535.897
533.233
563.701
532.293
518.724
474.593
526.465
563.377
477.92
538.021
480.247
525.276
490.087
536.08
570.053
574.44
543.487
568.451
497.708
521.091
508.036
501.515
549.036
560.195
519.283
549.419
539.305
526.576
O1s
L2822-6
0
0
0
0
0
0
0
6
Casa Info Follows
0
0
0
0
d:\yugin\demchenko\casaxps\l2822-6\24.vms
XPS
24
Al
1486.6
1e+037
1e+037
1e+037
1e+037
1e+037
FAT
1e+037
1e+037
1e+037
1e+037
1e+037
1e+037
1e+037
1e+037
O1s

-1
Binding Energy
eV
541
-0.1
1
Counts
d
pulse counting
1
1
1e+037
1e+037
1e+037
1e+037
1
MFP Exponent
d
0
161
0
1
556.384
575.21
540.034
496.316
540.256
597.44
563.946
494.56
471.824
465.974
525.932
538.42
523.75
507.48
474.824
537.644
456.582
539.678
507.48
528.508
518.482
553.628
525.474
486.018
545.812
490.284
478.154
483.63
533.648
487.824
439.204
548.074
575.628
504.088
500.494
547.574
549.636
496.13
478.134
563.23
496.796
549.37
494.506
506.67
568.764
529.782
520.134
539.798
512.454
498.424
565.424
514.144
466.688
517.018
508.502
580.068
567.718
560.562
576.046
570.29
581.964
569.586
552.596
597.812
596.856
674.796
614.164
646.184
673.606
660.59
713.466
709.674
646.414
741.394
676.108
622.702
684.9
634.966
661.23
606.86
685.032
571.068
633.468
606.446
597.852
574.114
583.798
556.252
655.412
598.548
589.52
594.204
609.446
560.39
607.838
568.884
616.952
574.474
558.11
594.036
540.148
541.494
478.272
492.482
556.446
481.452
554.94
539.87
502.778
545.406
511.77
472.85
515.81
512.106
557.478
482.25
532.566
573.208
446.818
513.372
492.62
511.66
518.986
413.284
494.15
537.972
485.464
538.392
543.772
526.336
549.506
540.336
555.438
480.426
525.142
464.718
489.71
477.554
454.736
490.41
481.86
553.238
516.356
486.832
532.894
492.844
559.4
530.336
537.452
552
472.25
530.312
551.782
510.346
506.102
541.548
528.13
547.37
531.052
557.316
492.446
Si2p
L2822-6
0
0
0
0
0
0
0
6
Casa Info Follows
0
0
0
0
d:\yugin\demchenko\casaxps\l2822-6\24.vms
XPS
24
Al
1486.6
1e+037
1e+037
1e+037
1e+037
1e+037
FAT
1e+037
1e+037
1e+037
1e+037
1e+037
1e+037
1e+037
1e+037
Si2p

-1
Binding Energy
eV
110
-0.1
1
Counts
d
pulse counting
1
1
1e+037
1e+037
1e+037
1e+037
1
MFP Exponent
d
0
161
0
1
285.548
280.366
285.944
271.784
226.252
279.964
272.464
284.026
301.67
289.546
270.428
267.792
269.844
256.596
271.988
325.506
246.054
262.074
252.204
311.428
230.324
248.128
235.858
254.188
252.122
253.886
198.256
219.284
262.268
240.606
285.65
253.998
261.644
236.076
214.028
232.02
216.182
246.208
289.406
216.268
252.182
279.278
281.98
268.352
297.946
260.086
313.514
274.412
310.298
314.412
319.86
349.928
332.036
333.98
371.512
346.252
341.968
347.752
318.64
331.968
345.906
318.228
347.736
331.282
308.258
276.458
301.594
312.036
280.252
284.148
306.412
351.088
278.748
317.528
302.162
329.6
274.13
258.336
287.938
327.648
306.608
329.616
337.63
288.732
386.036
402.178
419.96
499.552
490.98
590.136
672.404
826.826
957.674
1182.38
1453.59
1622.81
2141.44
2435.22
2769.06
2950.14
3141.82
3427.32
3569.24
3577.92
3601.68
3240.08
2936.92
2059.88
1550.92
1034.71
690.66
501.244
292.014
246.054
204.06
182.009
144.239
153.608
108.168
94.2046
124.003
94.1278
109.81
92.2244
104.063
103.778
102.085
101.952
129.849
102.304
105.886
127.858
108.116
123.818
114.207
99.8664
88.2642
85.9376
125.565
80.537
106.043
109.571
76.4262
105.744
119.997
88.1676
96.4518
127.551
102.043
123.756
109.966
85.9546
84.3522
78.0596
86.1364
105.523
84.5056
113.761
109.889
89.8238
90.0824
Si2p
L2800-5
0
0
0
0
0
0
0
14
Casa Info Follows
1
Calib M = 202.574 A = 202.2 BE ADD
0
1
CASA region (*Si 2p*) (*U 2 Tougaard*) 1382.3834 1388.9007 0.817 2 0 0 2705.4621 -650 0 0 (*Si 2p*) 28.0858 0
5
CASA comp (*Si 2p 3/2*) (*LA(1,1.5,250)*) Area 1785.3113 0.001 10000000 -1 1 MFWHM 0.73261384 0.24 6 -1 1 Position 1387.5015 1376.974 1392.974 -1 1 RSF 0.817 MASS 28.0858 INDEX -1 (*Si 2p*) CONST (**)
CASA comp (*Si 2p 1/2*) (*LA(1,1.5,250)*) Area 892.65563 0.001 10000000 0 0.5 MFWHM 0.73261384 0.24 6 0 1 Position 1386.8715 0 0 0 -0.63 RSF 0.817 MASS 28.0858 INDEX -1 (*Si 2p*) CONST (**)
CASA comp (*Si 2p 3/2 Si-Nb*) (*LA(1,1.5,250)*) Area 369.39868 0.001 10000000 -1 1 MFWHM 0.70665198 0.24 6 -1 1 Position 1387.8492 1376.974 1392.974 -1 1 RSF 0.817 MASS 28.0858 INDEX -1 (*Si 2p*) CONST (**)
CASA comp (*Si 2p 1/2 Si-Nb*) (*LA(1,1.5,250)*) Area 184.69934 0.001 10000000 2 0.5 MFWHM 0.70665198 0.16547927 4.1369818 2 1 Position 1387.2192 0 0 2 -0.63 RSF 0.817 MASS 28.0858 INDEX -1 (*Si 2p*) CONST (**)
CASA comp (*Si 2p SiOx*) (*GL(30)*) Area 138.07571 138.07571 138.09571 -1 1 MFWHM 1.48 1.46 1.48 -1 1 Position 1386.33 1386.33 1386.35 -1 -0.95 RSF 0.817 MASS 28.0858 INDEX -1 (*Si 2p*) CONST (**)
d:\yugin\demchenko\casaxps\l2800-5\12.vms
Z:\SI-NB-SI-GLASS\l2800-5_all_syr11.vms
XPS
12
Al
1486.6
1e+037
1e+037
1e+037
1e+037
1e+037
FAT
1e+037
1e+037
1e+037
1e+037
1e+037
1e+037
1e+037
1e+037
Si2p

-1
Binding Energy
eV
110
-0.1
1
Counts
d
pulse counting
1
1
1e+037
1e+037
1e+037
1e+037
2
MFP Exponent
d
0
PROPAGATION_CONVERGED
d
1
161
0
1
476.684
490.568
553.748
556.332
540.17
539.802
553.134
504.54
539.864
538.008
498.032
514.042
552.236
565.394
538.242
529.44
508.656
548.338
651.36
536.218
474.566
549.444
546.13
500.202
561.438
519.73
510.572
563.586
555.948
458.85
531.256
472.972
586.756
510.608
543.744
494.39
505.65
528.202
514.164
554.724
489.866
575.94
541.534
575.466
470.272
511.682
500.698
546.932
508.48
554.776
551.546
543.948
548.21
554.302
627.338
559.844
546.36
555.952
569.912
562.268
552.39
574.054
562.248
559.282
518.162
556.08
577.438
502.454
542.014
567.6
543.836
566.532
601.748
504.056
631.14
513.164
575.952
606.168
627.514
578.278
634.14
629.586
606.728
681.02
604.39
610.464
739.012
621.232
726.876
726.948
767.988
810.144
868.64
964.678
1047.2
1275.75
1431.76
1771.63
1935.28
2143.02
2413.84
2477.4
2723.78
2861.82
2997.12
2964.68
2812.16
2565.7
2181.52
1729.84
1470.44
1053.47
912.978
752.168
641.534
566.87
554.978
460.866
482.54
517.404
447.998
502.128
491.644
508.336
505.648
484.42
468.012
516.054
487.492
462.978
501.66
487.444
475.824
426.654
463.85
499.67
466.374
471.748
485.974
459.856
442.42
507.41
412.596
468.258
470.096
495.81
489.65
476.176
501.872
446.702
497.312
468.586
485.786
438.02
479.536
479.968
464.018
492.042
462.072
410.242
457.886
end of experiment